Workbook

Sheet BBM2022
B1: BBM $ | C1: # | D1: NAME | E1: POS | F1: TEAM | G1: PTS | H1: 3P | I1: REB | J1: AST | K1: STL | L1: BLK | M1: FG% | N1: FGA | O1: FT% | P1: FTA | Q1: FTA
A2: 12t round | B2: $ Projection | C2: Ranking | D2: Name | E2: Pos | F2: Team | G2: PTS | H2: 3P | I2: REB | J2: AST | K2: STL | L2: BLK | M2: FG% | N2: FGA | O2: FT% | P2: FTA
A3: =_xlfn.FLOOR.MATH(C3/12)+1 -> 1 | B3: 67.34172 | C3: 1 | D3: Nikola Jokic | E3: C | F3: DEN | G3: 26.821053 | H3: 1.1289474 | I3: 10.729079 | J3: 7.7136842 | K3: 1.1921053 | L3: 0.63118421 | M3: 0.56402768 | N3: 18.022632 | O3: 0.87500268 | P3: 6.1275
A4: =_xlfn.FLOOR.MATH(C4/12)+1 -> 1 | B4: 64.783779 | C4: 2 | D4: James Harden | E4: PG/SG | F4: BKN | G4: 25.374459 | H4: 2.952973 | I4: 7.8 | J4: 10.5 | K4: 1.275 | L4: 0.825 | M4: 0.46559225 | N4: 17.549865 | O4: 0.86600062 | P4: 7.02
A5: =_xlfn.FLOOR.MATH(C5/12)+1 -> 1 | B5: 64.520375 | C5: 3 | D5: Stephen Curry | E5: PG | F5: GSW | G5: 31.462361 | H5: 5.4933333 | I5: 5.4719444 | J5: 5.9095833 | K5: 1.2402778 | L5: 0.14597222 | M5: 0.4688722 | N5: 21.595556 | O5: 0.91300009 | P5: 6.2627778
A6: =_xlfn.FLOOR.MATH(C6/12)+1 -> 1 | B6: 51.130891 | C6: 4 | D6: Karl-Anthony Towns | E6: C | F6: MIN | G6: 24.803784 | H6: 2.4886486 | I6: 10.505946 | J6: 4.9612162 | K6: 0.72959459 | L6: 1.2402703 | M6: 0.50213571 | N6: 16.925811 | O6: 0.84899879 | P6: 6.2627027
A7: =_xlfn.FLOOR.MATH(C7/12)+1 -> 1 | B7: 50.740011 | C7: 5 | D7: Kevin Durant | E7: SF/PF | F7: BKN | G7: 25.923731 | H7: 2.2064179 | I7: 7.0125373 | J7: 4.7458209 | K7: 0.70835821 | L7: 1.2041791 | M7: 0.53846019 | N7: 16.999552 | O7: 0.88401132 | P7: 6.12
A8: =_xlfn.FLOOR.MATH(C8/12)+1 -> 1 | B8: 50.282927 | C8: 6 | D8: Damian Lillard | E8: PG | F8: POR | G8: 27.821184 | H8: 3.8598684 | I8: 4.1663158 | J8: 7.4235526 | K8: 0.90894737 | L8: 0.22723684 | M8: 0.45991433 | N8: 19.013553 | O8: 0.92000374 | P8: 7.0348684
A9: =_xlfn.FLOOR.MATH(C9/12)+1 -> 1 | B9: 50.17188 | C9: 7 | D9: Joel Embiid | E9: C | F9: PHI | G9: 27.557903 | H9: 1.1251613 | I9: 10.632419 | J9: 2.8701613 | K9: 0.91322581 | L9: 1.3698387 | M9: 0.50390117 | N9: 17.612581 | O9: 0.84999921 | P9: 10.215
A10: =_xlfn.FLOOR.MATH(C10/12)+1 -> 1 | B10: 46.661084 | C10: 8 | D10: Bradley Beal | E10: SG | F10: WAS | G10: 31.474242 | H10: 2.5018182 | I10: 4.4887879 | J10: 5.67 | K10: 1.1812121 | L10: 0.315 | M10: 0.47584982 | N10: 23.467424 | O10: 0.88400621 | P10: 7.5095455
A11: =_xlfn.FLOOR.MATH(C11/12)+1 -> 1 | B11: 45.653833 | C11: 9 | D11: Jayson Tatum | E11: SF/PF | F11: BOS | G11: 27.752 | H11: 3.092 | I11: 7.5749333 | J11: 4.6965333 | K11: 1.212 | L11: 0.53026667 | M11: 0.46078025 | N11: 21.2104 | O11: 0.86100447 | P11: 5.9388
A12: =_xlfn.FLOOR.MATH(C12/12)+1 -> 1 | B12: 45.13563 | C12: 10 | D12: Kyrie Irving | E12: PG/SG | F12: BKN | G12: 24.186531 | H12: 2.5183673 | I12: 4.674898 | J12: 5.1 | K12: 1.3459184 | L12: 0.63755102 | M12: 0.50097161 | N12: 18.273878 | O12: 0.91897928 | P12: 3.654898
A13: =_xlfn.FLOOR.MATH(C13/12)+1 -> 1 | B13: 43.973245 | C13: 11 | D13: Giannis Antetokounmpo | E13: PF | F13: MIL | G13: 27.862361 | H13: 1.0938889 | I13: 11.368472 | J13: 5.8630556 | K13: 1.1440278 | L13: 1.2155556 | M13: 0.57533039 | N13: 17.803056 | O13: 0.69200294 | P13: 9.0797222
A14: =_xlfn.FLOOR.MATH(C14/12)+1 -> 2 | B14: 43.524657 | C14: 12 | D14: Paul George | E14: SG/SF | F14: LAC | G14: 26.1825 | H14: 3.2467647 | I14: 6.8722059 | J14: 5.4697059 | K14: 1.1920588 | L14: 0.42073529 | M14: 0.45674082 | N14: 19.846176 | O14: 0.86500291 | P14: 5.5567647
... A221: =_xlfn.FLOOR.MATH(C221/12)+1 -> 19 | B221: 1 | C221: 219 | D221: Khem Birch | E221: C | F221: TOR | G221: 8.5838158 | H221: 0.29644737 | I221: 6.4009211 | J221: 1.5318421 | K221: 0.82065789 | L221: 0.87539474 | M221: 0.4922983 | N221: 6.8935526 | O221: 0.68002863 | P221: 2.2057895

Sheet Fantasypros
A1: Player | B1: Team | C1: Positions | D1: PTS | E1: REB | F1: AST | G1: BLK | H1: STL | I1: FG% | J1: FT% | K1: 3PM | L1: GP | M1: MIN | N1: TO
A2: Bradley Beal | B2: WAS | C2: SG,SF | D2: 30.2 | E2: 5 | F2: 5.7 | G2: 0.4 | H2: 1.3 | I2: 0.469 | J2: 0.867 | K2: 2.5 | L2: 73 | M2: 36.1 | N2: 3
A3: Stephen Curry | B3: GSW | C3: PG,SG | D3: 29.4 | E3: 5.3 | F3: 5.6 | G3: 0.2 | H3: 1.3 | I3: 0.474 | J3: 0.928 | K3: 5 | L3: 75 | M3: 34.7 | N3: 3.2
A4: Luka Doncic | B4: DAL | C4: PG,SG | D4: 29 | E4: 8.5 | F4: 9 | G4: 0.5 | H4: 1.1 | I4: 0.482 | J4: 0.747 | K4: 3.1 | L4: 78 | M4: 34.7 | N4: 4.2
A5: Zion Williamson | B5: NOR | C5: PF OUT | D5: 28.1 | E5: 7 | F5: 4.6 | G5: 0.7 | H5: 1 | I5: 0.614 | J5: 0.695 | K5: 0.2 | L5: 75 | M5: 33.4 | N5: 2.5
A6: Damian Lillard | B6: POR | C6: PG | D6: 27.7 | E6: 4.1 | F6: 7.1 | G6: 0.3 | H6: 0.9 | I6: 0.453 | J6: 0.914 | K6: 3.9 | L6: 77 | M6: 36 | N6: 2.8
A7: Giannis Antetokounmpo | B7: MIL | C7: PF,C | D7: 27.6 | E7: 11.2 | F7: 5.5 | G7: 1.1 | H7: 1.2 | I7: 0.58 | J7: 0.685 | K7: 1.1 | L7: 77 | M7: 33.2 | N7: 3.3
A8: Joel Embiid | B8: PHI | C8: PF,C | D8: 27 | E8: 11.2 | F8: 3 | G8: 1.4 | H8: 1 | I8: 0.499 | J8: 0.828 | K8: 1.2 | L8: 69 | M8: 30.9 | N8: 3.1
A9: Jayson Tatum | B9: BOS | C9: SF,PF | D9: 26.9 | E9: 7.2 | F9: 4.3 | G9: 0.6 | H9: 1.2 | I9: 0.458 | J9: 0.852 | K9: 3 | L9: 78 | M9: 35.6 | N9: 2.7
A10: Kevin Durant | B10: BKN | C10: SF,PF | D10: 26.5 | E10: 6.8 | F10: 4.9 | G10: 1.1 | H10: 0.7 | I10: 0.536 | J10: 0.889 | K10: 2.2 | L10: 72 | M10: 34.1 | N10: 3.1
A11: Nikola Jokic | B11: DEN | C11: PF,C | D11: 26.3 | E11: 10.7 | F11: 7.7 | G11: 0.8 | H11: 1.4 | I11: 0.552 | J11: 0.839 | K11: 1.4 | L11: 77 | M11: 35 | N11: 3.1
A12: Zach LaVine | B12: CHI | C12: SG,SF | D12: 26.2 | E12: 4.9 | F12: 4.5 | G12: 0.5 | H12: 0.8 | I12: 0.489 | J12: 0.843 | K12: 3.2 | L12: 74 | M12: 34.9 | N12: 3.2
A13: Donovan Mitchell | B13: UTH | C13: PG,SG | D13: 25.5 | E13: 4.3 | F13: 4.9 | G13: 0.3 | H13: 1.1 | I13: 0.444 | J13: 0.836 | K13: 3.1 | L13: 75 | M13: 34.2 | N13: 2.7
... A244: Taj Gibson | B244: NYK | C244: PF,C | D244: 3.9 | E244: 11.4 | F244: 0.5 | G244: 0.9 | H244: 0.5 | I244: 0.612 | J244: 0.747 | K244: 0 | L244: 53 | M244: 14.1 | N244: 0.7

Sheet Valorisation
A1: 14 | B1: Teams | D1: ALL | E1: for build | I1: 180 | J1: Players incl in Z | M1: SIMILAR PLAYERS | AQ1: https://www.reddit.com/r/fantasybball/comments/71bdq0/how_to_calculate_weighted_zscore_for_fg/
A2: 13 | B2: Players per roster | C2: Total budget | D2: =A1*A3 -> 2800 | E2: =A1*A3 -> 2800 | M2: https://www.fb-ninja.com/SimilarPlayers/
A3: 200 | B3: Budget | C3: Total Z | D3: =SUMIF(F6:F224,">0",F6:F224) -> 523.72725 | E3: =SUMIF(G6:G224,">0",G6:G224) -> 523.72725 | AG3: =AVERAGE(AG6:INDIRECT(ADDRESS(5 +$I1,COLUMN(AG2)))) -> -4.2311833e-15 | AH3: Avg | AI3: =AVERAGE(O6:INDIRECT(ADDRESS(5 +$I1,COLUMN(O2)))) -> 16.139106 | AJ3: =AVERAGE(P6:INDIRECT(ADDRESS(5 +$I1,COLUMN(P2)))) -> 1.724015 | AK3: =AVERAGE(Q6:INDIRECT(ADDRESS(5 +$I1,COLUMN(Q2)))) -> 5.7079459 | AL3: =AVERAGE(R6:INDIRECT(ADDRESS(5 +$I1,COLUMN(R2)))) -> 3.6244252 | AM3: =AVERAGE(S6:INDIRECT(ADDRESS(5 +$I1,COLUMN(S2)))) -> 0.98922855 | AN3: =AVERAGE(T6:INDIRECT(ADDRESS(5 +$I1,COLUMN(T2)))) -> 0.6706845 | AO3: =AVERAGE(AU6:INDIRECT(ADDRESS(5 +$I1,COLUMN(AU2)))) -> 5.754656e-16 | AP3: =AVERAGE(AV6:INDIRECT(ADDRESS(5 +$I1,COLUMNS($B2:AV2)))) -> -8.3878699e-16 | AS3: =AVERAGE(AQ6:INDIRECT(ADDRESS(5 +$I1,COLUMN(AQ2))))/AVERAGE(V6:INDIRECT(ADDRESS(5 +$I1,COLUMN(V2)))) -> 0.47597471 | AT3: =AVERAGE(AR6:INDIRECT(ADDRESS(5 +$I1,COLUMN(AR2))))/AVERAGE(X6:INDIRECT(ADDRESS(5 +$I1,COLUMN(X2)))) -> 0.80010269
A4: 2.8 | B4: zcorr | C4: price per Z | D4: =D2/D3 -> 5.3462943 | E4: =E2/E3 -> 5.3462943 | O4: 1 | P4: 1 | Q4: 1 | R4: 1 | S4: 1 | T4: 1 | U4: 1 | W4: 1 | AG4: =STDEV(AG6:INDIRECT(ADDRESS(5 +$I$1,COLUMN(AG3)))) -> 3.0410168 | AH4: Std | AI4: =STDEV(O6:INDIRECT(ADDRESS(5 +$I1,COLUMN(O2)))) -> 5.7512512 | AJ4: =STDEV(P6:INDIRECT(ADDRESS(5 +$I1,COLUMN(P2)))) -> 1.0070124 | AK4: =STDEV(Q6:INDIRECT(ADDRESS(5 +$I1,COLUMN(Q2)))) -> 2.3920498 | AL4: =STDEV(R6:INDIRECT(ADDRESS(5 +$I1,COLUMN(R2)))) -> 2.1002462 | AM4: =STDEV(S6:INDIRECT(ADDRESS(5 +$I1,COLUMN(S2)))) -> 0.31319278 | AN4: =STDEV(T6:INDIRECT(ADDRESS(5 +$I1,COLUMN(T2)))) -> 0.54373402 | AO4: =STDEV(AU6:INDIRECT(ADDRESS(5 +$I$1,COLUMN(AU3)))) -> 0.64297656 | AP4: =STDEV(AV6:INDIRECT(ADDRESS(5 +$I$1,COLUMN(AV3)))) -> 0.27848391
A5: RNK | B5: NAME | C5: BBM Val | D5: Calc val | E5: $ for build | F5: Z bumped | G5: Zbuild | H5: Available? | I5: Mine | J5: Playoff sched | K5: RNK | L5: NAME | M5: POS | N5: TEAM | O5: PTS | P5: 3P | Q5: REB | R5: AST | S5: STL | T5: BLK | U5: FG% | V5: FGA | W5: FT% | X5: FTA | Y5: vPTS | Z5: v3P | AA5: vREB | AB5: vAST | AC5: vSTL | AD5: vBLK | AE5: w FG v | AF5: w FT v | AG5: Build value | AH5: BuildZVal | AI5: vPTS | AJ5: v3P | AK5: vREB | AL5: vAST | AM5: vSTL | AN5: vBLK | AO5: weighted FG v | AP5: vWeighted FTv | AQ5: Made FG | AR5: Made FT | AS5: dFG% | AT5: dFT% | AU5: mFG | AV5: mFT
A6: 1 | B6: =L6 -> Nikola Jokic | C6: 67.34172 | D6: =F6*D$4 -> 68.452934 | E6: =G6*E$4 -> 68.452934 | F6: =SUM(AI6:AN6,AP6,AO6)+$A$4 -> 12.80381 | G6: =SUM(Y6:AF6)+$A$4 -> 12.80381 | H6: 1 | I6: 0 | J6: =VLOOKUP(N6,Schedule!#REF!,2,0) -> #REF! | K6: 1 | L6: Nikola Jokic | M6: C | N6: DEN | O6: 26.821053 | P6: 1.1289474 | Q6: 10.729079 | R6: 7.7136842 | S6: 1.1921053 | T6: 0.63118421 | U6: 0.56402768 | V6: 18.022632 | W6: 0.87500268 | X6: 6.1275 | Y6: =O$4*AI6 -> 1.8573257 | Z6: =P$4*AJ6 -> -0.59092382 | AA6: =Q$4*AK6 -> 2.0990922 | AB6: =R$4*AL6 -> 1.9470379 | AC6: =S$4*AM6 -> 0.64776944 | AD6: =T$4*AN6 -> -0.072646352 | AE6: =U$4*AO6 -> 2.4681248 | AF6: =AP6*W$4 -> 1.6480295 | AG6: =SUM(Y6:AF6) -> 10.00381 | AH6: =(AG6-AG$3)/AG$4 -> 3.2896266 | AI6: =(O6-AI$3)/AI$4 -> 1.8573257 | AJ6: =(P6-AJ$3)/AJ$4 -> -0.59092382 | AK6: =(Q6-AK$3)/AK$4 -> 2.0990922 | AL6: =(R6-AL$3)/AL$4 -> 1.9470379 | AM6: =(S6-AM$3)/AM$4 -> 0.64776944 | AN6: =(T6-AN$3)/AN$4 -> -0.072646352 | AO6: =(AU6-$AO$3)/$AO$4 -> 2.4681248 | AP6: =(AV6-$AP$3)/$AP$4 -> 1.6480295 | AQ6: =V6*U6 -> 10.165263 | AR6: =W6*X6 -> 5.3615789 | AS6: =(U6-AS$3) -> 0.088052979 | AT6: =(W6-AT$3) -> 0.074899992 | AU6: =AS6*V6 -> 1.5869464 | AV6: =AT6*X6 -> 0.4589497
A7: 2 | B7: =L7 -> James Harden | C7: 64.783779 | D7: =F7*D$4 -> 66.018721 | E7: =G7*E$4 -> 66.018721 | F7: =SUM(AI7:AN7,AP7,AO7)+$A$4 -> 12.348501 | G7: =SUM(Y7:AF7)+$A$4 -> 12.348501 | H7: 1 | I7: 0 | J7: =VLOOKUP(N7,Schedule!#REF!,2,0) -> #REF! | K7: 2 | L7: James Harden | M7: PG/SG | N7: BKN | O7: 25.374459 | P7: 2.952973 | Q7: 7.8 | R7: 10.5 | S7: 1.275 | T7: 0.825 | U7: 0.46559225 | V7: 17.549865 | W7: 0.86600062 | X7: 7.02 | Y7: =O$4*AI7 -> 1.605799 | Z7: =P$4*AJ7 -> 1.2204001 | AA7: =Q$4*AK7 -> 0.87458638 | AB7: =R$4*AL7 -> 3.2736995 | AC7: =S$4*AM7 -> 0.91244584 | AD7: =T$4*AN7 -> 0.28380695 | AE7: =U$4*AO7 -> -0.28338618 | AF7: =AP7*W$4 -> 1.6611496 | AG7: =SUM(Y7:AF7) -> 9.5485011 | AH7: =(AG7-AG$3)/AG$4 -> 3.1399042 | AI7: =(O7-AI$3)/AI$4 -> 1.605799 | AJ7: =(P7-AJ$3)/AJ$4 -> 1.2204001 | AK7: =(Q7-AK$3)/AK$4 -> 0.87458638 | AL7: =(R7-AL$3)/AL$4 -> 3.2736995 | AM7: =(S7-AM$3)/AM$4 -> 0.91244584 | AN7: =(T7-AN$3)/AN$4 -> 0.28380695 | AO7: =(AU7-$AO$3)/$AO$4 -> -0.28338618 | AP7: =(AV7-$AP$3)/$AP$4 -> 1.6611496 | AQ7: =V7*U7 -> 8.1710811 | AR7: =W7*X7 -> 6.0793243 | AS7: =(U7-AS$3) -> -0.010382455 | AT7: =(W7-AT$3) -> 0.065897924 | AU7: =AS7*V7 -> -0.18221067 | AV7: =AT7*X7 -> 0.46260343
A8: 3 | B8: =L8 -> Stephen Curry | C8: 64.520375 | D8: =F8*D$4 -> 65.939754 | E8: =G8*E$4 -> 65.939754 | F8: =SUM(AI8:AN8,AP8,AO8)+$A$4 -> 12.333731 | G8: =SUM(Y8:AF8)+$A$4 -> 12.333731 | H8: 1 | I8: 1 | J8: =VLOOKUP(N8,Schedule!#REF!,2,0) -> #REF! | K8: 3 | L8: Stephen Curry | M8: PG | N8: GSW | O8: 31.462361 | P8: 5.4933333 | Q8: 5.4719444 | R8: 5.9095833 | S8: 1.2402778 | T8: 0.14597222 | U8: 0.4688722 | V8: 21.595556 | W8: 0.91300009 | X8: 6.2627778 | Y8: =O$4*AI8 -> 2.6643342 | Z8: =P$4*AJ8 -> 3.7430705 | AA8: =Q$4*AK8 -> -0.098660748 | AB8: =R$4*AL8 -> 1.088043 | AC8: =S$4*AM8 -> 0.80158051 | AD8: =T$4*AN8 -> -0.96501646 | AE8: =U$4*AO8 -> -0.23855089 | AF8: =AP8*W$4 -> 2.5389306 | AG8: =SUM(Y8:AF8) -> 9.5337307 | AH8: =(AG8-AG$3)/AG$4 -> 3.1350471 | AI8: =(O8-AI$3)/AI$4 -> 2.6643342 | AJ8: =(P8-AJ$3)/AJ$4 -> 3.7430705 | AK8: =(Q8-AK$3)/AK$4 -> -0.098660748 | AL8: =(R8-AL$3)/AL$4 -> 1.088043 | AM8: =(S8-AM$3)/AM$4 -> 0.80158051 | AN8: =(T8-AN$3)/AN$4 -> -0.96501646 | AO8: =(AU8-$AO$3)/$AO$4 -> -0.23855089 | AP8: =(AV8-$AP$3)/$AP$4 -> 2.5389306 | AQ8: =V8*U8 -> 10.125556 | AR8: =W8*X8 -> 5.7179167 | AS8: =(U8-AS$3) -> -0.0071025093 | AT8: =(W8-AT$3) -> 0.1128974 | AU8: =AS8*V8 -> -0.15338263 | AV8: =AT8*X8 -> 0.70705131
A9: 4 | B9: =L9 -> Karl-Anthony Towns | C9: 51.130891 | D9: =F9*D$4 -> 51.939295 | E9: =G9*E$4 -> 51.939295 | F9: =SUM(AI9:AN9,AP9,AO9)+$A$4 -> 9.7150086 | G9: =SUM(Y9:AF9)+$A$4 -> 9.7150086 | H9: 1 | I9: 0 | J9: =VLOOKUP(N9,Schedule!#REF!,2,0) -> #REF! | K9: 4 | L9: Karl-Anthony Towns | M9: C | N9: MIN | O9: 24.803784 | P9: 2.4886486 | Q9: 10.505946 | R9: 4.9612162 | S9: 0.72959459 | T9: 1.2402703 | U9: 0.50213571 | V9: 16.925811 | W9: 0.84899879 | X9: 6.2627027 | Y9: =O$4*AI9 -> 1.5065727 | Z9: =P$4*AJ9 -> 0.75930911 | AA9: =Q$4*AK9 -> 2.0058112 | AB9: =R$4*AL9 -> 0.63649253 | AC9: =S$4*AM9 -> -0.82899087 | AD9: =T$4*AN9 -> 1.0475448 | AE9: =U$4*AO9 -> 0.68866623 | AF9: =AP9*W$4 -> 1.099603 | AG9: =SUM(Y9:AF9) -> 6.9150086 | AH9: =(AG9-AG$3)/AG$4 -> 2.2739134 | AI9: =(O9-AI$3)/AI$4 -> 1.5065727 | AJ9: =(P9-AJ$3)/AJ$4 -> 0.75930911 | AK9: =(Q9-AK$3)/AK$4 -> 2.0058112 | AL9: =(R9-AL$3)/AL$4 -> 0.63649253 | AM9: =(S9-AM$3)/AM$4 -> -0.82899087 | AN9: =(T9-AN$3)/AN$4 -> 1.0475448 | AO9: =(AU9-$AO$3)/$AO$4 -> 0.68866623 | AP9: =(AV9-$AP$3)/$AP$4 -> 1.099603 | AQ9: =V9*U9 -> 8.4990541 | AR9: =W9*X9 -> 5.317027 | AS9: =(U9-AS$3) -> 0.026161006 | AT9: =(W9-AT$3) -> 0.0488961 | AU9: =AS9*V9 -> 0.44279624 | AV9: =AT9*X9 -> 0.30622174
A10: 5 | B10: =L10 -> Kevin Durant | C10: 50.740011 | D10: =F10*D$4 -> 51.538658 | E10: =G10*E$4 -> 51.538658 | F10: =SUM(AI10:AN10,AP10,AO10)+$A$4 -> 9.6400713 | G10: =SUM(Y10:AF10)+$A$4 -> 9.6400713 | H10: 1 | I10: 0 | J10: =VLOOKUP(N10,Schedule!#REF!,2,0) -> #REF! | K10: 5 | L10: Kevin Durant | M10: SF/PF | N10: BKN | O10: 25.923731 | P10: 2.2064179 | Q10: 7.0125373 | R10: 4.7458209 | S10: 0.70835821 | T10: 1.2041791 | U10: 0.53846019 | V10: 16.999552 | W10: 0.88401132 | X10: 6.12 | Y10: =O$4*AI10 -> 1.7013038 | Z10: =P$4*AJ10 -> 0.4790437 | AA10: =Q$4*AK10 -> 0.54538642 | AB10: =R$4*AL10 -> 0.53393535 | AC10: =S$4*AM10 -> -0.89679698 | AD10: =T$4*AN10 -> 0.98116833 | AE10: =U$4*AO10 -> 1.6520435 | AF10: =AP10*W$4 -> 1.8439873 | AG10: =SUM(Y10:AF10) -> 6.8400713 | AH10: =(AG10-AG$3)/AG$4 -> 2.2492712 | AI10: =(O10-AI$3)/AI$4 -> 1.7013038 | AJ10: =(P10-AJ$3)/AJ$4 -> 0.4790437 | AK10: =(Q10-AK$3)/AK$4 -> 0.54538642 | AL10: =(R10-AL$3)/AL$4 -> 0.53393535 | AM10: =(S10-AM$3)/AM$4 -> -0.89679698 | AN10: =(T10-AN$3)/AN$4 -> 0.98116833 | AO10: =(AU10-$AO$3)/$AO$4 -> 1.6520435 | AP10: =(AV10-$AP$3)/$AP$4 -> 1.8439873 | AQ10: =V10*U10 -> 9.1535821 | AR10: =W10*X10 -> 5.4101493 | AS10: =(U10-AS$3) -> 0.062485483 | AT10: =(W10-AT$3) -> 0.083908624 | AU10: =AS10*V10 -> 1.0622252 | AV10: =AT10*X10 -> 0.51352078
A11: 6 | B11: =L11 -> Damian Lillard | C11: 50.282927 | D11: =F11*D$4 -> 51.317272 | E11: =G11*E$4 -> 51.317272 | F11: =SUM(AI11:AN11,AP11,AO11)+$A$4 -> 9.598662 | G11: =SUM(Y11:AF11)+$A$4 -> 9.598662 | H11: 1 | I11: 0 | J11: =VLOOKUP(N11,Schedule!#REF!,2,0) -> #REF! | K11: 6 | L11: Damian Lillard | M11: PG | N11: POR | O11: 27.821184 | P11: 3.8598684 | Q11: 4.1663158 | R11: 7.4235526 | S11: 0.90894737 | T11: 0.22723684 | U11: 0.45991433 | V11: 19.013553 | W11: 0.92000374 | X11: 7.0348684 | Y11: =O$4*AI11 -> 2.0312238 | Z11: =P$4*AJ11 -> 2.1209803 | AA11: =Q$4*AK11 -> -0.64448077 | AB11: =R$4*AL11 -> 1.8088962 | AC11: =S$4*AM11 -> -0.25633152 | AD11: =T$4*AN11 -> -0.8155599 | AE11: =U$4*AO11 -> -0.47492376 | AF11: =AP11*W$4 -> 3.0288576 | AG11: =SUM(Y11:AF11) -> 6.798662 | AH11: =(AG11-AG$3)/AG$4 -> 2.2356542 | AI11: =(O11-AI$3)/AI$4 -> 2.0312238 | AJ11: =(P11-AJ$3)/AJ$4 -> 2.1209803 | AK11: =(Q11-AK$3)/AK$4 -> -0.64448077 | AL11: =(R11-AL$3)/AL$4 -> 1.8088962 | AM11: =(S11-AM$3)/AM$4 -> -0.25633152 | AN11: =(T11-AN$3)/AN$4 -> -0.8155599 | AO11: =(AU11-$AO$3)/$AO$4 -> -0.47492376 | AP11: =(AV11-$AP$3)/$AP$4 -> 3.0288576 | AQ11: =V11*U11 -> 8.7446053 | AR11: =W11*X11 -> 6.4721053 | AS11: =(U11-AS$3) -> -0.016060378 | AT11: =(W11-AT$3) -> 0.11990105 | AU11: =AS11*V11 -> -0.30536485 | AV11: =AT11*X11 -> 0.8434881
A12: 7 | B12: =L12 -> Joel Embiid | C12: 50.17188 | D12: =F12*D$4 -> 50.943199 | E12: =G12*E$4 -> 50.943199 | F12: =SUM(AI12:AN12,AP12,AO12)+$A$4 -> 9.5286934 | G12: =SUM(Y12:AF12)+$A$4 -> 9.5286934 | H12: 1 | I12: 0 | J12: =VLOOKUP(N12,Schedule!#REF!,2,0) -> #REF! | K12: 7 | L12: Joel Embiid | M12: C | N12: PHI | O12: 27.557903 | P12: 1.1251613 | Q12: 10.632419 | R12: 2.8701613 | S12: 0.91322581 | T12: 1.3698387 | U12: 0.50390117 | V12: 17.612581 | W12: 0.84999921 | X12: 10.215 | Y12: =O$4*AI12 -> 1.9854458 | Z12: =P$4*AJ12 -> -0.59468353 | AA12: =Q$4*AK12 -> 2.0586836 | AB12: =R$4*AL12 -> -0.3591312 | AC12: =S$4*AM12 -> -0.2426708 | AD12: =T$4*AN12 -> 1.2858386 | AE12: =U$4*AO12 -> 0.76496898 | AF12: =AP12*W$4 -> 1.830242 | AG12: =SUM(Y12:AF12) -> 6.7286934 | AH12: =(AG12-AG$3)/AG$4 -> 2.2126459 | AI12: =(O12-AI$3)/AI$4 -> 1.9854458 | AJ12: =(P12-AJ$3)/AJ$4 -> -0.59468353 | AK12: =(Q12-AK$3)/AK$4 -> 2.0586836 | AL12: =(R12-AL$3)/AL$4 -> -0.3591312 | AM12: =(S12-AM$3)/AM$4 -> -0.2426708 | AN12: =(T12-AN$3)/AN$4 -> 1.2858386 | AO12: =(AU12-$AO$3)/$AO$4 -> 0.76496898 | AP12: =(AV12-$AP$3)/$AP$4 -> 1.830242 | AQ12: =V12*U12 -> 8.875 | AR12: =W12*X12 -> 8.6827419 | AS12: =(U12-AS$3) -> 0.027926465 | AT12: =(W12-AT$3) -> 0.049896519 | AU12: =AS12*V12 -> 0.49185712 | AV12: =AT12*X12 -> 0.50969294
A13: 8 | B13: =L13 -> Bradley Beal | C13: 46.661084 | D13: =F13*D$4 -> 47.688362 | E13: =G13*E$4 -> 47.688362 | F13: =SUM(AI13:AN13,AP13,AO13)+$A$4 -> 8.919891 | G13: =SUM(Y13:AF13)+$A$4 -> 8.919891 | H13: 1 | I13: 0 | J13: =VLOOKUP(N13,Schedule!#REF!,2,0) -> #REF! | K13: 8 | L13: Bradley Beal | M13: SG | N13: WAS | O13: 31.474242 | P13: 2.5018182 | Q13: 4.4887879 | R13: 5.67 | S13: 1.1812121 | T13: 0.315 | U13: 0.47584982 | V13: 23.467424 | W13: 0.88400621 | X13: 7.5095455 | Y13: =O$4*AI13 -> 2.6664001 | Z13: =P$4*AJ13 -> 0.77238694 | AA13: =Q$4*AK13 -> -0.50967083 | AB13: =R$4*AL13 -> 0.97396906 | AC13: =S$4*AM13 -> 0.6129885 | AD13: =T$4*AN13 -> -0.65415164 | AE13: =U$4*AO13 -> -0.0045579241 | AF13: =AP13*W$4 -> 2.2625268 | AG13: =SUM(Y13:AF13) -> 6.119891 | AH13: =(AG13-AG$3)/AG$4 -> 2.012449 | AI13: =(O13-AI$3)/AI$4 -> 2.6664001 | AJ13: =(P13-AJ$3)/AJ$4 -> 0.77238694 | AK13: =(Q13-AK$3)/AK$4 -> -0.50967083 | AL13: =(R13-AL$3)/AL$4 -> 0.97396906 | AM13: =(S13-AM$3)/AM$4 -> 0.6129885 | AN13: =(T13-AN$3)/AN$4 -> -0.65415164 | AO13: =(AU13-$AO$3)/$AO$4 -> -0.0045579241 | AP13: =(AV13-$AP$3)/$AP$4 -> 2.2625268 | AQ13: =V13*U13 -> 11.16697 | AR13: =W13*X13 -> 6.6384848 | AS13: =(U13-AS$3) -> -0.00012488113 | AT13: =(W13-AT$3) -> 0.083903523 | AU13: =AS13*V13 -> -0.0029306383 | AV13: =AT13*X13 -> 0.63007732
A14: 9 | B14: =L14 -> Jayson Tatum | C14: 45.653833 | D14: =F14*D$4 -> 46.615352 | E14: =G14*E$4 -> 46.615352 | F14: =SUM(AI14:AN14,AP14,AO14)+$A$4 -> 8.7191894 | G14: =SUM(Y14:AF14)+$A$4 -> 8.7191894 | H14: 1 | I14: 0 | J14: =VLOOKUP(N14,Schedule!#REF!,2,0) -> #REF! | K14: 9 | L14: Jayson Tatum | M14: SF/PF | N14: BOS | O14: 27.752 | P14: 3.092 | Q14: 7.5749333 | R14: 4.6965333 | S14: 1.212 | T14: 0.53026667 | U14: 0.46078025 | V14: 21.2104 | W14: 0.86100447 | X14: 5.9388 | Y14: =O$4*AI14 -> 2.0191944 | Z14: =P$4*AJ14 -> 1.358459 | AA14: =Q$4*AK14 -> 0.78049692 | AB14: =R$4*AL14 -> 0.51046783 | AC14: =S$4*AM14 -> 0.71129178 | AD14: =T$4*AN14 -> -0.25824729 | AE14: =U$4*AO14 -> -0.5012322 | AF14: =AP14*W$4 -> 1.2987589 | AG14: =SUM(Y14:AF14) -> 5.9191894 | AH14: =(AG14-AG$3)/AG$4 -> 1.9464508 | AI14: =(O14-AI$3)/AI$4 -> 2.0191944 | AJ14: =(P14-AJ$3)/AJ$4 -> 1.358459 | AK14: =(Q14-AK$3)/AK$4 -> 0.78049692 | AL14: =(R14-AL$3)/AL$4 -> 0.51046783 | AM14: =(S14-AM$3)/AM$4 -> 0.71129178 | AN14: =(T14-AN$3)/AN$4 -> -0.25824729 | AO14: =(AU14-$AO$3)/$AO$4 -> -0.5012322 | AP14: =(AV14-$AP$3)/$AP$4 -> 1.2987589 | AQ14: =V14*U14 -> 9.7733333 | AR14: =W14*X14 -> 5.1133333 | AS14: =(U14-AS$3) -> -0.015194459 | AT14: =(W14-AT$3) -> 0.060901776 | AU14: =AS14*V14 -> -0.32228055 | AV14: =AT14*X14 -> 0.36168347
A15: 10 | B15: =L15 -> Kyrie Irving | C15: 45.13563 | D15: =F15*D$4 -> 46.017258 | E15: =G15*E$4 -> 46.017258 | F15: =SUM(AI15:AN15,AP15,AO15)+$A$4 -> 8.6073186 | G15: =SUM(Y15:AF15)+$A$4 -> 8.6073186 | H15: 1 | I15: 0 | J15: =VLOOKUP(N15,Schedule!#REF!,2,0) -> #REF! | K15: 10 | L15: Kyrie Irving | M15: PG/SG | N15: BKN | O15: 24.186531 | P15: 2.5183673 | Q15: 4.674898 | R15: 5.1 | S15: 1.3459184 | T15: 0.63755102 | U15: 0.50097161 | V15: 18.273878 | W15: 0.91897928 | X15: 3.654898 | Y15: =O$4*AI15 -> 1.3992476 | Z15: =P$4*AJ15 -> 0.78882086 | AA15: =Q$4*AK15 -> -0.43186723 | AB15: =R$4*AL15 -> 0.7025723 | AC15: =S$4*AM15 -> 1.1388826 | AD15: =T$4*AN15 -> -0.060936932 | AE15: =U$4*AO15 -> 0.71043087 | AF15: =AP15*W$4 -> 1.5601685 | AG15: =SUM(Y15:AF15) -> 5.8073186 | AH15: =(AG15-AG$3)/AG$4 -> 1.9096635 | AI15: =(O15-AI$3)/AI$4 -> 1.3992476 | AJ15: =(P15-AJ$3)/AJ$4 -> 0.78882086 | AK15: =(Q15-AK$3)/AK$4 -> -0.43186723 | AL15: =(R15-AL$3)/AL$4 -> 0.7025723 | AM15: =(S15-AM$3)/AM$4 -> 1.1388826 | AN15: =(T15-AN$3)/AN$4 -> -0.060936932 | AO15: =(AU15-$AO$3)/$AO$4 -> 0.71043087 | AP15: =(AV15-$AP$3)/$AP$4 -> 1.5601685 | AQ15: =V15*U15 -> 9.1546939 | AR15: =W15*X15 -> 3.3587755 | AS15: =(U15-AS$3) -> 0.024996906 | AT15: =(W15-AT$3) -> 0.11887659 | AU15: =AS15*V15 -> 0.4567904 | AV15: =AT15*X15 -> 0.43448182
A16: 11 | B16: =L16 -> Giannis Antetokounmpo | C16: 43.973245 | D16: =F16*D$4 -> 44.736678 | E16: =G16*E$4 -> 44.736678 | F16: =SUM(AI16:AN16,AP16,AO16)+$A$4 -> 8.3677918 | G16: =SUM(Y16:AF16)+$A$4 -> 8.3677918 | H16: 1 | I16: 0 | J16: =VLOOKUP(N16,Schedule!#REF!,2,0) -> #REF! | K16: 11 | L16: Giannis Antetokounmpo | M16: PF | N16: MIL | O16: 27.862361 | P16: 1.0938889 | Q16: 11.368472 | R16: 5.8630556 | S16: 1.1440278 | T16: 1.2155556 | U16: 0.57533039 | V16: 17.803056 | W16: 0.69200294 | X16: 9.0797222 | Y16: =O$4*AI16 -> 2.0383834 | Z16: =P$4*AJ16 -> -0.62573817 | AA16: =Q$4*AK16 -> 2.3663916 | AB16: =R$4*AL16 -> 1.0658895 | AC16: =S$4*AM16 -> 0.4942618 | AD16: =T$4*AN16 -> 1.0020912 | AE16: =U$4*AO16 -> 2.7510097 | AF16: =AP16*W$4 -> -3.5244972 | AG16: =SUM(Y16:AF16) -> 5.5677918 | AH16: =(AG16-AG$3)/AG$4 -> 1.8308981 | AI16: =(O16-AI$3)/AI$4 -> 2.0383834 | AJ16: =(P16-AJ$3)/AJ$4 -> -0.62573817 | AK16: =(Q16-AK$3)/AK$4 -> 2.3663916 | AL16: =(R16-AL$3)/AL$4 -> 1.0658895 | AM16: =(S16-AM$3)/AM$4 -> 0.4942618 | AN16: =(T16-AN$3)/AN$4 -> 1.0020912 | AO16: =(AU16-$AO$3)/$AO$4 -> 2.7510097 | AP16: =(AV16-$AP$3)/$AP$4 -> -3.5244972 | AQ16: =V16*U16 -> 10.242639 | AR16: =W16*X16 -> 6.2831944 | AS16: =(U16-AS$3) -> 0.099355684 | AT16: =(W16-AT$3) -> -0.10809975 | AU16: =AS16*V16 -> 1.7688348 | AV16: =AT16*X16 -> -0.98151575
A17: 12 | B17: =L17 -> Paul George | C17: 43.524657 | D17: =F17*D$4 -> 44.443834 | E17: =G17*E$4 -> 44.443834 | F17: =SUM(AI17:AN17,AP17,AO17)+$A$4 -> 8.3130167 | G17: =SUM(Y17:AF17)+$A$4 -> 8.3130167 | H17: 1 | I17: 0 | J17: =VLOOKUP(N17,Schedule!#REF!,2,0) -> #REF! | K17: 12 | L17: Paul George | M17: SG/SF | N17: LAC | O17: 26.1825 | P17: 3.2467647 | Q17: 6.8722059 | R17: 5.4697059 | S17: 1.1920588 | T17: 0.42073529 | U17: 0.45674082 | V17: 19.846176 | W17: 0.86500291 | X17: 5.5567647 | Y17: =O$4*AI17 -> 1.7462972 | Z17: =P$4*AJ17 -> 1.512146 | AA17: =Q$4*AK17 -> 0.48672065 | AB17: =R$4*AL17 -> 0.87860208 | AC17: =S$4*AM17 -> 0.64762117 | AD17: =T$4*AN17 -> -0.45969022 | AE17: =U$4*AO17 -> -0.5936751 | AF17: =AP17*W$4 -> 1.2949949 | AG17: =SUM(Y17:AF17) -> 5.5130167 | AH17: =(AG17-AG$3)/AG$4 -> 1.812886 | AI17: =(O17-AI$3)/AI$4 -> 1.7462972 | AJ17: =(P17-AJ$3)/AJ$4 -> 1.512146 | AK17: =(Q17-AK$3)/AK$4 -> 0.48672065 | AL17: =(R17-AL$3)/AL$4 -> 0.87860208 | AM17: =(S17-AM$3)/AM$4 -> 0.64762117 | AN17: =(T17-AN$3)/AN$4 -> -0.45969022 | AO17: =(AU17-$AO$3)/$AO$4 -> -0.5936751 | AP17: =(AV17-$AP$3)/$AP$4 -> 1.2949949 | AQ17: =V17*U17 -> 9.0645588 | AR17: =W17*X17 -> 4.8066176 | AS17: =(U17-AS$3) -> -0.01923389 | AT17: =(W17-AT$3) -> 0.064900219 | AU17: =AS17*V17 -> -0.38171917 | AV17: =AT17*X17 -> 0.36063525
... A204: 199 | B204: =L204 -> Terance Mann | C204: 1 | D204: =F204*D$4 -> -10.67631 | E204: =G204*E$4 -> -10.67631 | F204: =SUM(AI204:AN204,AP204,AO204)+$A$4 -> -1.9969551 | G204: =SUM(Y204:AF204)+$A$4 -> -1.9969551 | H204: 1 | I204: 0 | J204: =VLOOKUP(N204,Schedule!#REF!,2,0) -> #REF! | K204: 199 | L204: Terance Mann | M204: SF | N204: LAC | O204: 9.9816667 | P204: 0.75576923 | Q204: 4.640641 | R204: 2.1141026 | S204: 0.56717949 | T204: 0.25782051 | U204: 0.50124327 | V204: 7.4246154 | W204: 0.82798452 | X204: 2.1532051 | Y204: =O$4*AI204 -> -1.0706261 | Z204: =P$4*AJ204 -> -0.96150331 | AA204: =Q$4*AK204 -> -0.44618839 | AB204: =R$4*AL204 -> -0.71911696 | AC204: =S$4*AM204 -> -1.3475696 | AD204: =T$4*AN204 -> -0.75931241 | AE204: =U$4*AO204 -> 0.29178255 | AF204: =AP204*W$4 -> 0.21557904 | AG204: =SUM(Y204:AF204) -> -4.7969551 | AH204: =(AG204-AG$3)/AG$4 -> -1.5774182 | AI204: =(O204-AI$3)/AI$4 -> -1.0706261 | AJ204: =(P204-AJ$3)/AJ$4 -> -0.96150331 | AK204: =(Q204-AK$3)/AK$4 -> -0.44618839 | AL204: =(R204-AL$3)/AL$4 -> -0.71911696 | AM204: =(S204-AM$3)/AM$4 -> -1.3475696 | AN204: =(T204-AN$3)/AN$4 -> -0.75931241 | AO204: =(AU204-$AO$3)/$AO$4 -> 0.29178255 | AP204: =(AV204-$AP$3)/$AP$4 -> 0.21557904 | AQ204: =V204*U204 -> 3.7215385 | AR204: =W204*X204 -> 1.7828205 | AS204: =(U204-AS$3) -> 0.02526856 | AT204: =(W204-AT$3) -> 0.027881827 | AU204: =AS204*V204 -> 0.18760934 | AV204: =AT204*X204 -> 0.060035294
A205: 200 | B205: =L205 -> Xavier Tillman | C205: 1 | D205: =F205*D$4 -> -9.7716698 | E205: =G205*E$4 -> -9.7716698 | F205: =SUM(AI205:AN205,AP205,AO205)+$A$4 -> -1.8277463 | G205: =SUM(Y205:AF205)+$A$4 -> -1.8277463 | H205: 1 | I205: 0 | K205: 200 | L205: Xavier Tillman | M205: PF | N205: MEM | O205: 7.8872973 | P205: 0.44094595 | Q205: 4.9354054 | R205: 1.7166216 | S205: 0.77243243 | T205: 0.60081081 | U205: 0.55447307 | V205: 5.9228378 | W205: 0.67403028 | X205: 1.302973 | Y205: =O$4*AI205 -> -1.434785 | Z205: =P$4*AJ205 -> -1.2741343 | AA205: =Q$4*AK205 -> -0.3229617 | AB205: =R$4*AL205 -> -0.90837142 | AC205: =S$4*AM205 -> -0.69221301 | AD205: =T$4*AN205 -> -0.12850712 | AE205: =U$4*AO205 -> 0.72309488 | AF205: =AP205*W$4 -> -0.5898687 | AG205: =SUM(Y205:AF205) -> -4.6277463 | AH205: =(AG205-AG$3)/AG$4 -> -1.521776 | AI205: =(O205-AI$3)/AI$4 -> -1.434785 | AJ205: =(P205-AJ$3)/AJ$4 -> -1.2741343 | AK205: =(Q205-AK$3)/AK$4 -> -0.3229617 | AL205: =(R205-AL$3)/AL$4 -> -0.90837142 | AM205: =(S205-AM$3)/AM$4 -> -0.69221301 | AN205: =(T205-AN$3)/AN$4 -> -0.12850712 | AO205: =(AU205-$AO$3)/$AO$4 -> 0.72309488 | AP205: =(AV205-$AP$3)/$AP$4 -> -0.5898687 | AQ205: =V205*U205 -> 3.2840541 | AR205: =W205*X205 -> 0.87824324 | AS205: =(U205-AS$3) -> 0.078498361 | AT205: =(W205-AT$3) -> -0.12607241 | AU205: =AS205*V205 -> 0.46493306 | AV205: =AT205*X205 -> -0.16426894
A206: 201 | B206: =L206 -> Torrey Craig | C206: 1 | D206: =F206*D$4 -> -12.213651 | E206: =G206*E$4 -> -12.213651 | F206: =SUM(AI206:AN206,AP206,AO206)+$A$4 -> -2.2845077 | G206: =SUM(Y206:AF206)+$A$4 -> -2.2845077 | H206: 1 | I206: 0 | K206: 201 | L206: Torrey Craig | M206: SF | N206: IND | O206: 7.2281818 | P206: 1.0681818 | Q206: 4.7133333 | R206: 1.1783333 | S206: 0.63121212 | T206: 0.63121212 | U206: 0.48220348 | V206: 5.8915152 | W206: 0.7379004 | X206: 0.6480303 | Y206: =O$4*AI206 -> -1.5493888 | Z206: =P$4*AJ206 -> -0.65126622 | AA206: =Q$4*AK206 -> -0.41579926 | AB206: =R$4*AL206 -> -1.1646691 | AC206: =S$4*AM206 -> -1.1431184 | AD206: =T$4*AN206 -> -0.07259502 | AE206: =U$4*AO206 -> 0.05707347 | AF206: =AP206*W$4 -> -0.14474435 | AG206: =SUM(Y206:AF206) -> -5.0845077 | AH206: =(AG206-AG$3)/AG$4 -> -1.6719762 | AI206: =(O206-AI$3)/AI$4 -> -1.5493888 | AJ206: =(P206-AJ$3)/AJ$4 -> -0.65126622 | AK206: =(Q206-AK$3)/AK$4 -> -0.41579926 | AL206: =(R206-AL$3)/AL$4 -> -1.1646691 | AM206: =(S206-AM$3)/AM$4 -> -1.1431184 | AN206: =(T206-AN$3)/AN$4 -> -0.07259502 | AO206: =(AU206-$AO$3)/$AO$4 -> 0.05707347 | AP206: =(AV206-$AP$3)/$AP$4 -> -0.14474435 | AQ206: =V206*U206 -> 2.8409091 | AR206: =W206*X206 -> 0.47818182 | AS206: =(U206-AS$3) -> 0.0062287718 | AT206: =(W206-AT$3) -> -0.062202294 | AU206: =AS206*V206 -> 0.036696904 | AV206: =AT206*X206 -> -0.040308972
A207: 202 | B207: =L207 -> Aleksej Pokusevski | C207: 1 | D207: =F207*D$4 -> -6.1958134 | E207: =G207*E$4 -> -6.1958134 | F207: =SUM(AI207:AN207,AP207,AO207)+$A$4 -> -1.1588987 | G207: =SUM(Y207:AF207)+$A$4 -> -1.1588987 | H207: 1 | I207: 0 | K207: 202 | L207: Aleksej Pokusevski | M207: PF | N207: OKC | O207: 11.152432 | P207: 1.8193243 | Q207: 5.46 | R207: 2.8513514 | S207: 0.48527027 | T207: 1.0313514 | U207: 0.38784678 | V207: 10.799054 | W207: 0.73803316 | X207: 1.2958108 | Y207: =O$4*AI207 -> -0.86705891 | Z207: =P$4*AJ207 -> 0.094645661 | AA207: =Q$4*AK207 -> -0.10365414 | AB207: =R$4*AL207 -> -0.36808726 | AC207: =S$4*AM207 -> -1.6090993 | AD207: =T$4*AN207 -> 0.66331485 | AE207: =U$4*AO207 -> -1.4801445 | AF207: =AP207*W$4 -> -0.28881513 | AG207: =SUM(Y207:AF207) -> -3.9588987 | AH207: =(AG207-AG$3)/AG$4 -> -1.3018339 | AI207: =(O207-AI$3)/AI$4 -> -0.86705891 | AJ207: =(P207-AJ$3)/AJ$4 -> 0.094645661 | AK207: =(Q207-AK$3)/AK$4 -> -0.10365414 | AL207: =(R207-AL$3)/AL$4 -> -0.36808726 | AM207: =(S207-AM$3)/AM$4 -> -1.6090993 | AN207: =(T207-AN$3)/AN$4 -> 0.66331485 | AO207: =(AU207-$AO$3)/$AO$4 -> -1.4801445 | AP207: =(AV207-$AP$3)/$AP$4 -> -0.28881513 | AQ207: =V207*U207 -> 4.1883784 | AR207: =W207*X207 -> 0.95635135 | AS207: =(U207-AS$3) -> -0.088127922 | AT207: =(W207-AT$3) -> -0.062069529 | AU207: =AS207*V207 -> -0.95169819 | AV207: =AT207*X207 -> -0.080430366
A208: 203 | B208: =L208 -> Patrick Beverley | C208: 1 | D208: =F208*D$4 -> -9.0997491 | E208: =G208*E$4 -> -9.0997491 | F208: =SUM(AI208:AN208,AP208,AO208)+$A$4 -> -1.7020666 | G208: =SUM(Y208:AF208)+$A$4 -> -1.7020666 | H208: 1 | I208: 0 | K208: 203 | L208: Patrick Beverley | M208: PG | N208: MIN | O208: 7.4464516 | P208: 1.5077419 | Q208: 3.5406452 | R208: 2.5964516 | S208: 0.75532258 | T208: 0.66096774 | U208: 0.4219161 | V208: 5.9479032 | W208: 0.77304772 | X208: 1.1896774 | Y208: =O$4*AI208 -> -1.5114371 | Z208: =P$4*AJ208 -> -0.21476701 | AA208: =Q$4*AK208 -> -0.90604332 | AB208: =R$4*AL208 -> -0.48945386 | AC208: =S$4*AM208 -> -0.74684343 | AD208: =T$4*AN208 -> -0.017870432 | AE208: =U$4*AO208 -> -0.50007322 | AF208: =AP208*W$4 -> -0.11557826 | AG208: =SUM(Y208:AF208) -> -4.5020666 | AH208: =(AG208-AG$3)/AG$4 -> -1.4804478 | AI208: =(O208-AI$3)/AI$4 -> -1.5114371 | AJ208: =(P208-AJ$3)/AJ$4 -> -0.21476701 | AK208: =(Q208-AK$3)/AK$4 -> -0.90604332 | AL208: =(R208-AL$3)/AL$4 -> -0.48945386 | AM208: =(S208-AM$3)/AM$4 -> -0.74684343 | AN208: =(T208-AN$3)/AN$4 -> -0.017870432 | AO208: =(AU208-$AO$3)/$AO$4 -> -0.50007322 | AP208: =(AV208-$AP$3)/$AP$4 -> -0.11557826 | AQ208: =V208*U208 -> 2.5095161 | AR208: =W208*X208 -> 0.91967742 | AS208: =(U208-AS$3) -> -0.054058606 | AT208: =(W208-AT$3) -> -0.027054969 | AU208: =AS208*V208 -> -0.32153536 | AV208: =AT208*X208 -> -0.032186686
A209: 204 | B209: =L209 -> Grayson Allen | C209: 1 | D209: =F209*D$4 -> -7.5032825 | E209: =G209*E$4 -> -7.5032825 | F209: =SUM(AI209:AN209,AP209,AO209)+$A$4 -> -1.4034548 | G209: =SUM(Y209:AF209)+$A$4 -> -1.4034548 | H209: 1 | I209: 0 | K209: 204 | L209: Grayson Allen | M209: SG | N209: MIL | O209: 10.440597 | P209: 2.0876119 | Q209: 3.25 | R209: 2.0583582 | S209: 0.81253731 | T209: 0.10835821 | U209: 0.43070736 | V209: 8.0159701 | W209: 0.86001773 | X209: 1.6835821 | Y209: =O$4*AI209 -> -0.99082944 | Z209: =P$4*AJ209 -> 0.36106504 | AA209: =Q$4*AK209 -> -1.027548 | AB209: =R$4*AL209 -> -0.74565878 | AC209: =S$4*AM209 -> -0.56416127 | AD209: =T$4*AN209 -> -1.0341937 | AE209: =U$4*AO209 -> -0.56434672 | AF209: =AP209*W$4 -> 0.36221801 | AG209: =SUM(Y209:AF209) -> -4.2034548 | AH209: =(AG209-AG$3)/AG$4 -> -1.3822531 | AI209: =(O209-AI$3)/AI$4 -> -0.99082944 | AJ209: =(P209-AJ$3)/AJ$4 -> 0.36106504 | AK209: =(Q209-AK$3)/AK$4 -> -1.027548 | AL209: =(R209-AL$3)/AL$4 -> -0.74565878 | AM209: =(S209-AM$3)/AM$4 -> -0.56416127 | AN209: =(T209-AN$3)/AN$4 -> -1.0341937 | AO209: =(AU209-$AO$3)/$AO$4 -> -0.56434672 | AP209: =(AV209-$AP$3)/$AP$4 -> 0.36221801 | AQ209: =V209*U209 -> 3.4525373 | AR209: =W209*X209 -> 1.4479104 | AS209: =(U209-AS$3) -> -0.045267349 | AT209: =(W209-AT$3) -> 0.059915039 | AU209: =AS209*V209 -> -0.36286172 | AV209: =AT209*X209 -> 0.10087189
A210: 205 | B210: =L210 -> Kenyon Martin Jr. | C210: 1 | D210: =F210*D$4 -> -10.922598 | E210: =G210*E$4 -> -10.922598 | F210: =SUM(AI210:AN210,AP210,AO210)+$A$4 -> -2.0430222 | G210: =SUM(Y210:AF210)+$A$4 -> -2.0430222 | H210: 1 | I210: 0 | K210: 205 | L210: Kenyon Martin Jr. | M210: SF | N210: HOU | O210: 8.8304054 | P210: 0.78837838 | Q210: 4.9568919 | R210: 0.99135135 | S210: 0.61364865 | T210: 0.84972973 | U210: 0.50814574 | V210: 6.5612162 | W210: 0.72198551 | X210: 1.902973 | Y210: =O$4*AI210 -> -1.2708018 | Z210: =P$4*AJ210 -> -0.92912124 | AA210: =Q$4*AK210 -> -0.31397924 | AB210: =R$4*AL210 -> -1.2536977 | AC210: =S$4*AM210 -> -1.1991972 | AD210: =T$4*AN210 -> 0.32928825 | AE210: =U$4*AO210 -> 0.3282874 | AF210: =AP210*W$4 -> -0.53380061 | AG210: =SUM(Y210:AF210) -> -4.8430222 | AH210: =(AG210-AG$3)/AG$4 -> -1.5925668 | AI210: =(O210-AI$3)/AI$4 -> -1.2708018 | AJ210: =(P210-AJ$3)/AJ$4 -> -0.92912124 | AK210: =(Q210-AK$3)/AK$4 -> -0.31397924 | AL210: =(R210-AL$3)/AL$4 -> -1.2536977 | AM210: =(S210-AM$3)/AM$4 -> -1.1991972 | AN210: =(T210-AN$3)/AN$4 -> 0.32928825 | AO210: =(AU210-$AO$3)/$AO$4 -> 0.3282874 | AP210: =(AV210-$AP$3)/$AP$4 -> -0.53380061 | AQ210: =V210*U210 -> 3.3340541 | AR210: =W210*X210 -> 1.3739189 | AS210: =(U210-AS$3) -> 0.032171032 | AT210: =(W210-AT$3) -> -0.078117178 | AU210: =AS210*V210 -> 0.2110811 | AV210: =AT210*X210 -> -0.14865488
A211: 206 | B211: =L211 -> Kentavious Caldwell-Pope | C211: 1 | D211: =F211*D$4 -> -8.1920794 | E211: =G211*E$4 -> -8.1920794 | F211: =SUM(AI211:AN211,AP211,AO211)+$A$4 -> -1.5322911 | G211: =SUM(Y211:AF211)+$A$4 -> -1.5322911 | H211: 1 | I211: 0 | K211: 206 | L211: Kentavious Caldwell-Pope | M211: SG/SF | N211: WAS | O211: 9.2689474 | P211: 1.5485526 | Q211: 2.6161842 | R211: 1.9906579 | S211: 0.91 | T211: 0.39815789 | U211: 0.43656866 | V211: 7.2228947 | W211: 0.8510217 | X211: 1.6613158 | Y211: =O$4*AI211 -> -1.1945503 | Z211: =P$4*AJ211 -> -0.1742405 | AA211: =Q$4*AK211 -> -1.2925156 | AB211: =R$4*AL211 -> -0.77789325 | AC211: =S$4*AM211 -> -0.25297055 | AD211: =T$4*AN211 -> -0.50121309 | AE211: =U$4*AO211 -> -0.44266889 | AF211: =AP211*W$4 -> 0.30376101 | AG211: =SUM(Y211:AF211) -> -4.3322911 | AH211: =(AG211-AG$3)/AG$4 -> -1.4246193 | AI211: =(O211-AI$3)/AI$4 -> -1.1945503 | AJ211: =(P211-AJ$3)/AJ$4 -> -0.1742405 | AK211: =(Q211-AK$3)/AK$4 -> -1.2925156 | AL211: =(R211-AL$3)/AL$4 -> -0.77789325 | AM211: =(S211-AM$3)/AM$4 -> -0.25297055 | AN211: =(T211-AN$3)/AN$4 -> -0.50121309 | AO211: =(AU211-$AO$3)/$AO$4 -> -0.44266889 | AP211: =(AV211-$AP$3)/$AP$4 -> 0.30376101 | AQ211: =V211*U211 -> 3.1532895 | AR211: =W211*X211 -> 1.4138158 | AS211: =(U211-AS$3) -> -0.039406046 | AT211: =(W211-AT$3) -> 0.05091901 | AU211: =AS211*V211 -> -0.28462572 | AV211: =AT211*X211 -> 0.084592554
A212: 207 | B212: =L212 -> Doug McDermott | C212: 1 | D212: =F212*D$4 -> -11.54908 | E212: =G212*E$4 -> -11.54908 | F212: =SUM(AI212:AN212,AP212,AO212)+$A$4 -> -2.1602027 | G212: =SUM(Y212:AF212)+$A$4 -> -2.1602027 | H212: 1 | I212: 0 | K212: 207 | L212: Doug McDermott | M212: SF/PF | N212: SAS | O212: 13.905333 | P212: 1.8332 | Q212: 3.2950667 | R212: 1.3634667 | S212: 0.34093333 | T212: 0.1136 | U212: 0.49510469 | V212: 10.9084 | W212: 0.83200908 | X212: 1.5270667 | Y212: =O$4*AI212 -> -0.38839769 | Z212: =P$4*AJ212 -> 0.10842471 | AA212: =Q$4*AK212 -> -1.0087078 | AB212: =R$4*AL212 -> -1.0765207 | AC212: =S$4*AM212 -> -2.0699558 | AD212: =T$4*AN212 -> -1.0245533 | AE212: =U$4*AO212 -> 0.3245492 | AF212: =AP212*W$4 -> 0.1749587 | AG212: =SUM(Y212:AF212) -> -4.9602027 | AH212: =(AG212-AG$3)/AG$4 -> -1.6311001 | AI212: =(O212-AI$3)/AI$4 -> -0.38839769 | AJ212: =(P212-AJ$3)/AJ$4 -> 0.10842471 | AK212: =(Q212-AK$3)/AK$4 -> -1.0087078 | AL212: =(R212-AL$3)/AL$4 -> -1.0765207 | AM212: =(S212-AM$3)/AM$4 -> -2.0699558 | AN212: =(T212-AN$3)/AN$4 -> -1.0245533 | AO212: =(AU212-$AO$3)/$AO$4 -> 0.3245492 | AP212: =(AV212-$AP$3)/$AP$4 -> 0.1749587 | AQ212: =V212*U212 -> 5.4008 | AR212: =W212*X212 -> 1.2705333 | AS212: =(U212-AS$3) -> 0.019129985 | AT212: =(W212-AT$3) -> 0.031906389 | AU212: =AS212*V212 -> 0.20867753 | AV212: =AT212*X212 -> 0.048723183
A213: 208 | B213: =L213 -> Kent Bazemore | C213: 1 | D213: =F213*D$4 -> -11.237842 | E213: =G213*E$4 -> -11.237842 | F213: =SUM(AI213:AN213,AP213,AO213)+$A$4 -> -2.1019871 | G213: =SUM(Y213:AF213)+$A$4 -> -2.1019871 | H213: 1 | I213: 0 | K213: 208 | L213: Kent Bazemore | M213: SG/SF | N213: LAL | O213: 6.4113636 | P213: 0.94606061 | Q213: 3.1768182 | R213: 1.319697 | S213: 1.2218182 | T213: 0.48878788 | U213: 0.43475187 | V213: 5.5719697 | W213: 0.69595513 | X213: 0.89151515 | Y213: =O$4*AI213 -> -1.6914132 | Z213: =P$4*AJ213 -> -0.77253704 | AA213: =Q$4*AK213 -> -1.0581417 | AB213: =R$4*AL213 -> -1.097361 | AC213: =S$4*AM213 -> 0.74264046 | AD213: =T$4*AN213 -> -0.33453236 | AE213: =U$4*AO213 -> -0.35723292 | AF213: =AP213*W$4 -> -0.33340931 | AG213: =SUM(Y213:AF213) -> -4.9019871 | AH213: =(AG213-AG$3)/AG$4 -> -1.6119566 | AI213: =(O213-AI$3)/AI$4 -> -1.6914132 | AJ213: =(P213-AJ$3)/AJ$4 -> -0.77253704 | AK213: =(Q213-AK$3)/AK$4 -> -1.0581417 | AL213: =(R213-AL$3)/AL$4 -> -1.097361 | AM213: =(S213-AM$3)/AM$4 -> 0.74264046 | AN213: =(T213-AN$3)/AN$4 -> -0.33453236 | AO213: =(AU213-$AO$3)/$AO$4 -> -0.35723292 | AP213: =(AV213-$AP$3)/$AP$4 -> -0.33340931 | AQ213: =V213*U213 -> 2.4224242 | AR213: =W213*X213 -> 0.62045455 | AS213: =(U213-AS$3) -> -0.041222836 | AT213: =(W213-AT$3) -> -0.10414756 | AU213: =AS213*V213 -> -0.22969239 | AV213: =AT213*X213 -> -0.092849127
A214: 209 | B214: =L214 -> Kendrick Nunn | C214: 1 | D214: =F214*D$4 -> -13.334242 | E214: =G214*E$4 -> -13.334242 | F214: =SUM(AI214:AN214,AP214,AO214)+$A$4 -> -2.4941092 | G214: =SUM(Y214:AF214)+$A$4 -> -2.4941092 | H214: 1 | I214: 0 | K214: 209 | L214: Kendrick Nunn | M214: SG | N214: LAL | O214: 9.6045714 | P214: 1.4858571 | Q214: 2.057 | R214: 1.87 | S214: 0.70128571 | T214: 0.187 | U214: 0.47398033 | V214: 7.9472857 | W214: 0.92001797 | X214: 0.63585714 | Y214: =O$4*AI214 -> -1.1361936 | Z214: =P$4*AJ214 -> -0.2364994 | AA214: =Q$4*AK214 -> -1.5262834 | AB214: =R$4*AL214 -> -0.83534266 | AC214: =S$4*AM214 -> -0.9193789 | AD214: =T$4*AN214 -> -0.88956086 | AE214: =U$4*AO214 -> -0.024650715 | AF214: =AP214*W$4 -> 0.27380034 | AG214: =SUM(Y214:AF214) -> -5.2941092 | AH214: =(AG214-AG$3)/AG$4 -> -1.740901 | AI214: =(O214-AI$3)/AI$4 -> -1.1361936 | AJ214: =(P214-AJ$3)/AJ$4 -> -0.2364994 | AK214: =(Q214-AK$3)/AK$4 -> -1.5262834 | AL214: =(R214-AL$3)/AL$4 -> -0.83534266 | AM214: =(S214-AM$3)/AM$4 -> -0.9193789 | AN214: =(T214-AN$3)/AN$4 -> -0.88956086 | AO214: =(AU214-$AO$3)/$AO$4 -> -0.024650715 | AP214: =(AV214-$AP$3)/$AP$4 -> 0.27380034 | AQ214: =V214*U214 -> 3.7668571 | AR214: =W214*X214 -> 0.585 | AS214: =(U214-AS$3) -> -0.0019943705 | AT214: =(W214-AT$3) -> 0.11991528 | AU214: =AS214*V214 -> -0.015849832 | AV214: =AT214*X214 -> 0.076248988
A215: 210 | B215: =L215 -> Delon Wright | C215: 1 | D215: =F215*D$4 -> -11.355342 | E215: =G215*E$4 -> -11.355342 | F215: =SUM(AI215:AN215,AP215,AO215)+$A$4 -> -2.123965 | G215: =SUM(Y215:AF215)+$A$4 -> -2.123965 | H215: 1 | I215: 0 | K215: 210 | L215: Delon Wright | M215: PG/SG | N215: ATL | O215: 5.82 | P215: 0.62558824 | Q215: 2.8895588 | R215: 2.85 | S215: 1.1083824 | T215: 0.27705882 | U215: 0.4639688 | V215: 4.7895588 | W215: 0.78292908 | X215: 0.95794118 | Y215: =O$4*AI215 -> -1.7942367 | Z215: =P$4*AJ215 -> -1.0907778 | AA215: =Q$4*AK215 -> -1.1782309 | AB215: =R$4*AL215 -> -0.36873069 | AC215: =S$4*AM215 -> 0.38044875 | AD215: =T$4*AN215 -> -0.72393057 | AE215: =U$4*AO215 -> -0.089432446 | AF215: =AP215*W$4 -> -0.059074558 | AG215: =SUM(Y215:AF215) -> -4.923965 | AH215: =(AG215-AG$3)/AG$4 -> -1.6191838 | AI215: =(O215-AI$3)/AI$4 -> -1.7942367 | AJ215: =(P215-AJ$3)/AJ$4 -> -1.0907778 | AK215: =(Q215-AK$3)/AK$4 -> -1.1782309 | AL215: =(R215-AL$3)/AL$4 -> -0.36873069 | AM215: =(S215-AM$3)/AM$4 -> 0.38044875 | AN215: =(T215-AN$3)/AN$4 -> -0.72393057 | AO215: =(AU215-$AO$3)/$AO$4 -> -0.089432446 | AP215: =(AV215-$AP$3)/$AP$4 -> -0.059074558 | AQ215: =V215*U215 -> 2.2222059 | AR215: =W215*X215 -> 0.75 | AS215: =(U215-AS$3) -> -0.0120059 | AT215: =(W215-AT$3) -> -0.017173616 | AU215: =AS215*V215 -> -0.057502967 | AV215: =AT215*X215 -> -0.016451314
A216: 211 | B216: =L216 -> Maxi Kleber | C216: 1 | D216: =F216*D$4 -> -8.3184942 | E216: =G216*E$4 -> -8.3184942 | F216: =SUM(AI216:AN216,AP216,AO216)+$A$4 -> -1.5559365 | G216: =SUM(Y216:AF216)+$A$4 -> -1.5559365 | H216: 1 | I216: 0 | K216: 211 | L216: Maxi Kleber | M216: PF | N216: DAL | O216: 7.7402703 | P216: 1.9071622 | Q216: 5.0331081 | R216: 1.312973 | S216: 0.49243243 | T216: 0.76594595 | U216: 0.42259771 | V216: 6.1821622 | W216: 0.8940779 | X216: 0.68 | Y216: =O$4*AI216 -> -1.4603493 | Z216: =P$4*AJ216 -> 0.18187184 | AA216: =Q$4*AK216 -> -0.28211694 | AB216: =R$4*AL216 -> -1.1005625 | AC216: =S$4*AM216 -> -1.5862311 | AD216: =T$4*AN216 -> 0.17519861 | AE216: =U$4*AO216 -> -0.51321505 | AF216: =AP216*W$4 -> 0.22946799 | AG216: =SUM(Y216:AF216) -> -4.3559365 | AH216: =(AG216-AG$3)/AG$4 -> -1.4323948 | AI216: =(O216-AI$3)/AI$4 -> -1.4603493 | AJ216: =(P216-AJ$3)/AJ$4 -> 0.18187184 | AK216: =(Q216-AK$3)/AK$4 -> -0.28211694 | AL216: =(R216-AL$3)/AL$4 -> -1.1005625 | AM216: =(S216-AM$3)/AM$4 -> -1.5862311 | AN216: =(T216-AN$3)/AN$4 -> 0.17519861 | AO216: =(AU216-$AO$3)/$AO$4 -> -0.51321505 | AP216: =(AV216-$AP$3)/$AP$4 -> 0.22946799 | AQ216: =V216*U216 -> 2.6125676 | AR216: =W216*X216 -> 0.60797297 | AS216: =(U216-AS$3) -> -0.053376996 | AT216: =(W216-AT$3) -> 0.09397521 | AU216: =AS216*V216 -> -0.32998524 | AV216: =AT216*X216 -> 0.063903143
... A224: 219 | B224: =L224 -> Khem Birch | C224: 1 | D224: =F224*D$4 -> -8.4244806 | E224: =G224*E$4 -> -8.4244806 | F224: =SUM(AI224:AN224,AP224,AO224)+$A$4 -> -1.5757607 | G224: =SUM(Y224:AF224)+$A$4 -> -1.5757607 | H224: 1 | I224: 0 | K224: 219 | L224: Khem Birch | M224: C | N224: TOR | O224: 8.5838158 | P224: 0.29644737 | Q224: 6.4009211 | R224: 1.5318421 | S224: 0.82065789 | T224: 0.87539474 | U224: 0.4922983 | V224: 6.8935526 | W224: 0.68002863 | X224: 2.2057895 | Y224: =O$4*AI224 -> -1.3136777 | Z224: =P$4*AJ224 -> -1.4176267 | AA224: =Q$4*AK224 -> 0.28969932 | AB224: =R$4*AL224 -> -0.99635135 | AC224: =S$4*AM224 -> -0.53823289 | AD224: =T$4*AN224 -> 0.37648965 | AE224: =U$4*AO224 -> 0.17501031 | AF224: =AP224*W$4 -> -0.95107145 | AG224: =SUM(Y224:AF224) -> -4.3757607 | AH224: =(AG224-AG$3)/AG$4 -> -1.4389137 | AI224: =(O224-AI$3)/AI$4 -> -1.3136777 | AJ224: =(P224-AJ$3)/AJ$4 -> -1.4176267 | AK224: =(Q224-AK$3)/AK$4 -> 0.28969932 | AL224: =(R224-AL$3)/AL$4 -> -0.99635135 | AM224: =(S224-AM$3)/AM$4 -> -0.53823289 | AN224: =(T224-AN$3)/AN$4 -> 0.37648965 | AO224: =(AU224-$AO$3)/$AO$4 -> 0.17501031 | AP224: =(AV224-$AP$3)/$AP$4 -> -0.95107145 | AQ224: =V224*U224 -> 3.3936842 | AR224: =W224*X224 -> 1.5 | AS224: =(U224-AS$3) -> 0.01632359 | AT224: =(W224-AT$3) -> -0.12007406 | AU224: =AS224*V224 -> 0.11252753 | AV224: =AT224*X224 -> -0.2648581

Sheet RNK cats
C1: CATs | D1: PTS | E1: 3P | F1: REB | G1: AST | H1: STL | I1: BLK | J1: FG% | K1: FT%
D2: 0 | E2: 1 | F2: 1 | G2: 0 | H2: 1 | I2: 1 | J2: 1 | K2: 1
A3: RNK | B3: NAME | C3: Projected | D3: vPTS | E3: v3P | F3: vREB | G3: vAST | H3: vSTL | I3: vBLK | J3: w FG v | K3: w FT v | L3: Sum | M3: Available? | N3: Pos
A4: 1 | B4: =VLOOKUP($A4,Valorisation!$A$5:$AF$224,2,0) -> Nikola Jokic | C4: =VLOOKUP($A4,Valorisation!$A$5:$AF$224,4,0) -> 68.452934 | D4: =VLOOKUP($A4,Valorisation!$A$5:$AZ$224,35+COLUMN(D3)-4,0)*D$2 -> 0 | E4: =VLOOKUP($A4,Valorisation!$A$5:$AZ$224,35+COLUMN(E3)-4,0)*E$2 -> -0.59092382 | F4: =VLOOKUP($A4,Valorisation!$A$5:$AZ$224,35+COLUMN(F3)-4,0)*F$2 -> 2.0990922 | G4: =VLOOKUP($A4,Valorisation!$A$5:$AZ$224,35+COLUMN(G3)-4,0)*G$2 -> 0 | H4: =VLOOKUP($A4,Valorisation!$A$5:$AZ$224,35+COLUMN(H3)-4,0)*H$2 -> 0.64776944 | I4: =VLOOKUP($A4,Valorisation!$A$5:$AZ$224,35+COLUMN(I3)-4,0)*I$2 -> -0.072646352 | J4: =VLOOKUP($A4,Valorisation!$A$5:$AZ$224,35+COLUMN(J3)-4,0)*J$2 -> 2.4681248 | K4: =VLOOKUP($A4,Valorisation!$A$5:$AZ$224,35+COLUMN(K3)-4,0)*K$2 -> 1.6480295 | L4: =SUM(D4:K4) -> 6.1994459 | M4: =VLOOKUP($A4,Valorisation!$A$5:$AF$224,8,0) -> 1 | N4: =VLOOKUP($A4,Valorisation!$A$5:$AF$224,13,0) -> C
A5: 3 | B5: =VLOOKUP($A5,Valorisation!$A$5:$AF$224,2,0) -> Stephen Curry | C5: =VLOOKUP($A5,Valorisation!$A$5:$AF$224,4,0) -> 65.939754 | D5: =VLOOKUP($A5,Valorisation!$A$5:$AZ$224,35+COLUMN(D4)-4,0)*D$2 -> 0 | E5: =VLOOKUP($A5,Valorisation!$A$5:$AZ$224,35+COLUMN(E4)-4,0)*E$2 -> 3.7430705 | F5: =VLOOKUP($A5,Valorisation!$A$5:$AZ$224,35+COLUMN(F4)-4,0)*F$2 -> -0.098660748 | G5: =VLOOKUP($A5,Valorisation!$A$5:$AZ$224,35+COLUMN(G4)-4,0)*G$2 -> 0 | H5: =VLOOKUP($A5,Valorisation!$A$5:$AZ$224,35+COLUMN(H4)-4,0)*H$2 -> 0.80158051 | I5: =VLOOKUP($A5,Valorisation!$A$5:$AZ$224,35+COLUMN(I4)-4,0)*I$2 -> -0.96501646 | J5: =VLOOKUP($A5,Valorisation!$A$5:$AZ$224,35+COLUMN(J4)-4,0)*J$2 -> -0.23855089 | K5: =VLOOKUP($A5,Valorisation!$A$5:$AZ$224,35+COLUMN(K4)-4,0)*K$2 -> 2.5389306 | L5: =SUM(D5:K5) -> 5.7813535 | M5: =VLOOKUP($A5,Valorisation!$A$5:$AF$224,8,0) -> 1 | N5: =VLOOKUP($A5,Valorisation!$A$5:$AF$224,13,0) -> PG
A6: 7 | B6: =VLOOKUP($A6,Valorisation!$A$5:$AF$224,2,0) -> Joel Embiid | C6: =VLOOKUP($A6,Valorisation!$A$5:$AF$224,4,0) -> 50.943199 | D6: =VLOOKUP($A6,Valorisation!$A$5:$AZ$224,35+COLUMN(D5)-4,0)*D$2 -> 0 | E6: =VLOOKUP($A6,Valorisation!$A$5:$AZ$224,35+COLUMN(E5)-4,0)*E$2 -> -0.59468353 | F6: =VLOOKUP($A6,Valorisation!$A$5:$AZ$224,35+COLUMN(F5)-4,0)*F$2 -> 2.0586836 | G6: =VLOOKUP($A6,Valorisation!$A$5:$AZ$224,35+COLUMN(G5)-4,0)*G$2 -> 0 | H6: =VLOOKUP($A6,Valorisation!$A$5:$AZ$224,35+COLUMN(H5)-4,0)*H$2 -> -0.2426708 | I6: =VLOOKUP($A6,Valorisation!$A$5:$AZ$224,35+COLUMN(I5)-4,0)*I$2 -> 1.2858386 | J6: =VLOOKUP($A6,Valorisation!$A$5:$AZ$224,35+COLUMN(J5)-4,0)*J$2 -> 0.76496898 | K6: =VLOOKUP($A6,Valorisation!$A$5:$AZ$224,35+COLUMN(K5)-4,0)*K$2 -> 1.830242 | L6: =SUM(D6:K6) -> 5.1023788 | M6: =VLOOKUP($A6,Valorisation!$A$5:$AF$224,8,0) -> 1 | N6: =VLOOKUP($A6,Valorisation!$A$5:$AF$224,13,0) -> C
A7: 4 | B7: =VLOOKUP($A7,Valorisation!$A$5:$AF$224,2,0) -> Karl-Anthony Towns | C7: =VLOOKUP($A7,Valorisation!$A$5:$AF$224,4,0) -> 51.939295 | D7: =VLOOKUP($A7,Valorisation!$A$5:$AZ$224,35+COLUMN(D6)-4,0)*D$2 -> 0 | E7: =VLOOKUP($A7,Valorisation!$A$5:$AZ$224,35+COLUMN(E6)-4,0)*E$2 -> 0.75930911 | F7: =VLOOKUP($A7,Valorisation!$A$5:$AZ$224,35+COLUMN(F6)-4,0)*F$2 -> 2.0058112 | G7: =VLOOKUP($A7,Valorisation!$A$5:$AZ$224,35+COLUMN(G6)-4,0)*G$2 -> 0 | H7: =VLOOKUP($A7,Valorisation!$A$5:$AZ$224,35+COLUMN(H6)-4,0)*H$2 -> -0.82899087 | I7: =VLOOKUP($A7,Valorisation!$A$5:$AZ$224,35+COLUMN(I6)-4,0)*I$2 -> 1.0475448 | J7: =VLOOKUP($A7,Valorisation!$A$5:$AZ$224,35+COLUMN(J6)-4,0)*J$2 -> 0.68866623 | K7: =VLOOKUP($A7,Valorisation!$A$5:$AZ$224,35+COLUMN(K6)-4,0)*K$2 -> 1.099603 | L7: =SUM(D7:K7) -> 4.7719435 | M7: =VLOOKUP($A7,Valorisation!$A$5:$AF$224,8,0) -> 1 | N7: =VLOOKUP($A7,Valorisation!$A$5:$AF$224,13,0) -> C
A8: 2 | B8: =VLOOKUP($A8,Valorisation!$A$5:$AF$224,2,0) -> James Harden | C8: =VLOOKUP($A8,Valorisation!$A$5:$AF$224,4,0) -> 66.018721 | D8: =VLOOKUP($A8,Valorisation!$A$5:$AZ$224,35+COLUMN(D7)-4,0)*D$2 -> 0 | E8: =VLOOKUP($A8,Valorisation!$A$5:$AZ$224,35+COLUMN(E7)-4,0)*E$2 -> 1.2204001 | F8: =VLOOKUP($A8,Valorisation!$A$5:$AZ$224,35+COLUMN(F7)-4,0)*F$2 -> 0.87458638 | G8: =VLOOKUP($A8,Valorisation!$A$5:$AZ$224,35+COLUMN(G7)-4,0)*G$2 -> 0 | H8: =VLOOKUP($A8,Valorisation!$A$5:$AZ$224,35+COLUMN(H7)-4,0)*H$2 -> 0.91244584 | I8: =VLOOKUP($A8,Valorisation!$A$5:$AZ$224,35+COLUMN(I7)-4,0)*I$2 -> 0.28380695 | J8: =VLOOKUP($A8,Valorisation!$A$5:$AZ$224,35+COLUMN(J7)-4,0)*J$2 -> -0.28338618 | K8: =VLOOKUP($A8,Valorisation!$A$5:$AZ$224,35+COLUMN(K7)-4,0)*K$2 -> 1.6611496 | L8: =SUM(D8:K8) -> 4.6690027 | M8: =VLOOKUP($A8,Valorisation!$A$5:$AF$224,8,0) -> 1 | N8: =VLOOKUP($A8,Valorisation!$A$5:$AF$224,13,0) -> PG/SG
A9: 5 | B9: =VLOOKUP($A9,Valorisation!$A$5:$AF$224,2,0) -> Kevin Durant | C9: =VLOOKUP($A9,Valorisation!$A$5:$AF$224,4,0) -> 51.538658 | D9: =VLOOKUP($A9,Valorisation!$A$5:$AZ$224,35+COLUMN(D8)-4,0)*D$2 -> 0 | E9: =VLOOKUP($A9,Valorisation!$A$5:$AZ$224,35+COLUMN(E8)-4,0)*E$2 -> 0.4790437 | F9: =VLOOKUP($A9,Valorisation!$A$5:$AZ$224,35+COLUMN(F8)-4,0)*F$2 -> 0.54538642 | G9: =VLOOKUP($A9,Valorisation!$A$5:$AZ$224,35+COLUMN(G8)-4,0)*G$2 -> 0 | H9: =VLOOKUP($A9,Valorisation!$A$5:$AZ$224,35+COLUMN(H8)-4,0)*H$2 -> -0.89679698 | I9: =VLOOKUP($A9,Valorisation!$A$5:$AZ$224,35+COLUMN(I8)-4,0)*I$2 -> 0.98116833 | J9: =VLOOKUP($A9,Valorisation!$A$5:$AZ$224,35+COLUMN(J8)-4,0)*J$2 -> 1.6520435 | K9: =VLOOKUP($A9,Valorisation!$A$5:$AZ$224,35+COLUMN(K8)-4,0)*K$2 -> 1.8439873 | L9: =SUM(D9:K9) -> 4.6048322 | M9: =VLOOKUP($A9,Valorisation!$A$5:$AF$224,8,0) -> 1 | N9: =VLOOKUP($A9,Valorisation!$A$5:$AF$224,13,0) -> SF/PF
A10: 25 | B10: =VLOOKUP($A10,Valorisation!$A$5:$AF$224,2,0) -> Rudy Gobert | C10: =VLOOKUP($A10,Valorisation!$A$5:$AF$224,4,0) -> 30.664019 | D10: =VLOOKUP($A10,Valorisation!$A$5:$AZ$224,35+COLUMN(D9)-4,0)*D$2 -> 0 | E10: =VLOOKUP($A10,Valorisation!$A$5:$AZ$224,35+COLUMN(E9)-4,0)*E$2 -> -1.7120097 | F10: =VLOOKUP($A10,Valorisation!$A$5:$AZ$224,35+COLUMN(F9)-4,0)*F$2 -> 3.4982668 | G10: =VLOOKUP($A10,Valorisation!$A$5:$AZ$224,35+COLUMN(G9)-4,0)*G$2 -> 0 | H10: =VLOOKUP($A10,Valorisation!$A$5:$AZ$224,35+COLUMN(H9)-4,0)*H$2 -> -0.98734252 | I10: =VLOOKUP($A10,Valorisation!$A$5:$AZ$224,35+COLUMN(I9)-4,0)*I$2 -> 3.7689668 | J10: =VLOOKUP($A10,Valorisation!$A$5:$AZ$224,35+COLUMN(J9)-4,0)*J$2 -> 2.511219 | K10: =VLOOKUP($A10,Valorisation!$A$5:$AZ$224,35+COLUMN(K9)-4,0)*K$2 -> -2.5706321 | L10: =SUM(D10:K10) -> 4.5084683 | M10: =VLOOKUP($A10,Valorisation!$A$5:$AF$224,8,0) -> 1 | N10: =VLOOKUP($A10,Valorisation!$A$5:$AF$224,13,0) -> C
A11: 15 | B11: =VLOOKUP($A11,Valorisation!$A$5:$AF$224,2,0) -> Anthony Davis | C11: =VLOOKUP($A11,Valorisation!$A$5:$AF$224,4,0) -> 41.511962 | D11: =VLOOKUP($A11,Valorisation!$A$5:$AZ$224,35+COLUMN(D10)-4,0)*D$2 -> 0 | E11: =VLOOKUP($A11,Valorisation!$A$5:$AZ$224,35+COLUMN(E10)-4,0)*E$2 -> -0.8255394 | F11: =VLOOKUP($A11,Valorisation!$A$5:$AZ$224,35+COLUMN(F10)-4,0)*F$2 -> 0.66262803 | G11: =VLOOKUP($A11,Valorisation!$A$5:$AZ$224,35+COLUMN(G10)-4,0)*G$2 -> 0 | H11: =VLOOKUP($A11,Valorisation!$A$5:$AZ$224,35+COLUMN(H10)-4,0)*H$2 -> 1.0956814 | I11: =VLOOKUP($A11,Valorisation!$A$5:$AZ$224,35+COLUMN(I10)-4,0)*I$2 -> 2.6355659 | J11: =VLOOKUP($A11,Valorisation!$A$5:$AZ$224,35+COLUMN(J10)-4,0)*J$2 -> 0.72670792 | K11: =VLOOKUP($A11,Valorisation!$A$5:$AZ$224,35+COLUMN(K10)-4,0)*K$2 -> -0.14369708 | L11: =SUM(D11:K11) -> 4.1513468 | M11: =VLOOKUP($A11,Valorisation!$A$5:$AF$224,8,0) -> 1 | N11: =VLOOKUP($A11,Valorisation!$A$5:$AF$224,13,0) -> PF
A12: 46 | B12: =VLOOKUP($A12,Valorisation!$A$5:$AF$224,2,0) -> Robert Williams | C12: =VLOOKUP($A12,Valorisation!$A$5:$AF$224,4,0) -> 26.7056 | D12: =VLOOKUP($A12,Valorisation!$A$5:$AZ$224,35+COLUMN(D11)-4,0)*D$2 -> 0 | E12: =VLOOKUP($A12,Valorisation!$A$5:$AZ$224,35+COLUMN(E11)-4,0)*E$2 -> -1.7120097 | F12: =VLOOKUP($A12,Valorisation!$A$5:$AZ$224,35+COLUMN(F11)-4,0)*F$2 -> 1.3742846 | G12: =VLOOKUP($A12,Valorisation!$A$5:$AZ$224,35+COLUMN(G11)-4,0)*G$2 -> 0 | H12: =VLOOKUP($A12,Valorisation!$A$5:$AZ$224,35+COLUMN(H11)-4,0)*H$2 -> 0.36868161 | I12: =VLOOKUP($A12,Valorisation!$A$5:$AZ$224,35+COLUMN(I11)-4,0)*I$2 -> 2.6365058 | J12: =VLOOKUP($A12,Valorisation!$A$5:$AZ$224,35+COLUMN(J11)-4,0)*J$2 -> 2.4051787 | K12: =VLOOKUP($A12,Valorisation!$A$5:$AZ$224,35+COLUMN(K11)-4,0)*K$2 -> -1.1675939 | L12: =SUM(D12:K12) -> 3.9050471 | M12: =VLOOKUP($A12,Valorisation!$A$5:$AF$224,8,0) -> 1 | N12: =VLOOKUP($A12,Valorisation!$A$5:$AF$224,13,0) -> PF/C
A13: 10 | B13: =VLOOKUP($A13,Valorisation!$A$5:$AF$224,2,0) -> Kyrie Irving | C13: =VLOOKUP($A13,Valorisation!$A$5:$AF$224,4,0) -> 46.017258 | D13: =VLOOKUP($A13,Valorisation!$A$5:$AZ$224,35+COLUMN(D12)-4,0)*D$2 -> 0 | E13: =VLOOKUP($A13,Valorisation!$A$5:$AZ$224,35+COLUMN(E12)-4,0)*E$2 -> 0.78882086 | F13: =VLOOKUP($A13,Valorisation!$A$5:$AZ$224,35+COLUMN(F12)-4,0)*F$2 -> -0.43186723 | G13: =VLOOKUP($A13,Valorisation!$A$5:$AZ$224,35+COLUMN(G12)-4,0)*G$2 -> 0 | H13: =VLOOKUP($A13,Valorisation!$A$5:$AZ$224,35+COLUMN(H12)-4,0)*H$2 -> 1.1388826 | I13: =VLOOKUP($A13,Valorisation!$A$5:$AZ$224,35+COLUMN(I12)-4,0)*I$2 -> -0.060936932 | J13: =VLOOKUP($A13,Valorisation!$A$5:$AZ$224,35+COLUMN(J12)-4,0)*J$2 -> 0.71043087 | K13: =VLOOKUP($A13,Valorisation!$A$5:$AZ$224,35+COLUMN(K12)-4,0)*K$2 -> 1.5601685 | L13: =SUM(D13:K13) -> 3.7054987 | M13: =VLOOKUP($A13,Valorisation!$A$5:$AF$224,8,0) -> 1 | N13: =VLOOKUP($A13,Valorisation!$A$5:$AF$224,13,0) -> PG/SG
A14: 9 | B14: =VLOOKUP($A14,Valorisation!$A$5:$AF$224,2,0) -> Jayson Tatum | C14: =VLOOKUP($A14,Valorisation!$A$5:$AF$224,4,0) -> 46.615352 | D14: =VLOOKUP($A14,Valorisation!$A$5:$AZ$224,35+COLUMN(D13)-4,0)*D$2 -> 0 | E14: =VLOOKUP($A14,Valorisation!$A$5:$AZ$224,35+COLUMN(E13)-4,0)*E$2 -> 1.358459 | F14: =VLOOKUP($A14,Valorisation!$A$5:$AZ$224,35+COLUMN(F13)-4,0)*F$2 -> 0.78049692 | G14: =VLOOKUP($A14,Valorisation!$A$5:$AZ$224,35+COLUMN(G13)-4,0)*G$2 -> 0 | H14: =VLOOKUP($A14,Valorisation!$A$5:$AZ$224,35+COLUMN(H13)-4,0)*H$2 -> 0.71129178 | I14: =VLOOKUP($A14,Valorisation!$A$5:$AZ$224,35+COLUMN(I13)-4,0)*I$2 -> -0.25824729 | J14: =VLOOKUP($A14,Valorisation!$A$5:$AZ$224,35+COLUMN(J13)-4,0)*J$2 -> -0.5012322 | K14: =VLOOKUP($A14,Valorisation!$A$5:$AZ$224,35+COLUMN(K13)-4,0)*K$2 -> 1.2987589 | L14: =SUM(D14:K14) -> 3.3895272 | M14: =VLOOKUP($A14,Valorisation!$A$5:$AF$224,8,0) -> 1 | N14: =VLOOKUP($A14,Valorisation!$A$5:$AF$224,13,0) -> SF/PF
A15: 44 | B15: =VLOOKUP($A15,Valorisation!$A$5:$AF$224,2,0) -> Deandre Ayton | C15: =VLOOKUP($A15,Valorisation!$A$5:$AF$224,4,0) -> 26.902505 | D15: =VLOOKUP($A15,Valorisation!$A$5:$AZ$224,35+COLUMN(D14)-4,0)*D$2 -> 0 | E15: =VLOOKUP($A15,Valorisation!$A$5:$AZ$224,35+COLUMN(E14)-4,0)*E$2 -> -1.6348882 | F15: =VLOOKUP($A15,Valorisation!$A$5:$AZ$224,35+COLUMN(F14)-4,0)*F$2 -> 2.2491614 | G15: =VLOOKUP($A15,Valorisation!$A$5:$AZ$224,35+COLUMN(G14)-4,0)*G$2 -> 0 | H15: =VLOOKUP($A15,Valorisation!$A$5:$AZ$224,35+COLUMN(H14)-4,0)*H$2 -> -0.62990117 | I15: =VLOOKUP($A15,Valorisation!$A$5:$AZ$224,35+COLUMN(I14)-4,0)*I$2 -> 1.1941785 | J15: =VLOOKUP($A15,Valorisation!$A$5:$AZ$224,35+COLUMN(J14)-4,0)*J$2 -> 2.3559205 | K15: =VLOOKUP($A15,Valorisation!$A$5:$AZ$224,35+COLUMN(K14)-4,0)*K$2 -> -0.17184304 | L15: =SUM(D15:K15) -> 3.3626281 | M15: =VLOOKUP($A15,Valorisation!$A$5:$AF$224,8,0) -> 1 | N15: =VLOOKUP($A15,Valorisation!$A$5:$AF$224,13,0) -> C
... A159: 122 | B159: =VLOOKUP($A159,Valorisation!$A$5:$AF$224,2,0) -> Spencer Dinwiddie | C159: =VLOOKUP($A159,Valorisation!$A$5:$AF$224,4,0) -> 4.185083 | D159: =VLOOKUP($A159,Valorisation!$A$5:$AZ$224,35+COLUMN(D158)-4,0)*D$2 -> 0 | E159: =VLOOKUP($A159,Valorisation!$A$5:$AZ$224,35+COLUMN(E158)-4,0)*E$2 -> 0.36063919 | F159: =VLOOKUP($A159,Valorisation!$A$5:$AZ$224,35+COLUMN(F158)-4,0)*F$2 -> -0.69622743 | G159: =VLOOKUP($A159,Valorisation!$A$5:$AZ$224,35+COLUMN(G158)-4,0)*G$2 -> 0 | H159: =VLOOKUP($A159,Valorisation!$A$5:$AZ$224,35+COLUMN(H158)-4,0)*H$2 -> -1.3147294 | I159: =VLOOKUP($A159,Valorisation!$A$5:$AZ$224,35+COLUMN(I158)-4,0)*I$2 -> -0.7024613 | J159: =VLOOKUP($A159,Valorisation!$A$5:$AZ$224,35+COLUMN(J158)-4,0)*J$2 -> -1.3854277 | K159: =VLOOKUP($A159,Valorisation!$A$5:$AZ$224,35+COLUMN(K158)-4,0)*K$2 -> -0.73565497 | L159: =SUM(D159:K159) -> -4.4738616 | M159: =VLOOKUP($A159,Valorisation!$A$5:$AF$224,8,0) -> 1 | N159: =VLOOKUP($A159,Valorisation!$A$5:$AF$224,13,0) -> PG/SG

Sheet My Team
B1: AVERAGE | E1: =AVERAGE(E8:E34) -> 31.462361 | F1: =AVERAGE(F8:F34) -> 5.4933333 | G1: =AVERAGE(G8:G34) -> 5.4719444 | H1: =AVERAGE(H8:H34) -> 5.9095833 | I1: =AVERAGE(I8:I34) -> 1.2402778 | J1: =AVERAGE(J8:J34) -> 0.14597222 | K1: =AVERAGE(K8:K34) -> 0.4688722 | L1: =AVERAGE(L8:L34) -> 21.595556 | ... V1: =AVERAGE(V8:V34) -> 2.5389306
E2: =E7 -> PTS | F2: =F7 -> 3P | G2: =G7 -> REB | H2: =H7 -> AST | I2: =I7 -> STL | J2: =J7 -> BLK | K2: =K7 -> FG% | L2: =L7 -> FGA | ... V2: =V7 -> w FT v
B4: Mine | C4: 1
B7: NAME | C7: POS | D7: TEAM | E7: PTS | F7: 3P | G7: REB | H7: AST | I7: STL | J7: BLK | K7: FG% | L7: FGA | M7: FT% | N7: FTA | O7: vPTS | P7: v3P | Q7: vREB | R7: vAST | S7: vSTL | T7: vBLK | U7: w FG v | V7: w FT v | AF7: Average auctioned value
A8: 1 | B8: Stephen Curry | C8: PG | D8: GSW | E8: 31.462361 | F8: 5.4933333 | G8: 5.4719444 | H8: 5.9095833 | I8: 1.2402778 | J8: 0.14597222 | K8: 0.4688722 | L8: 21.595556 | M8: 0.91300009 | N8: 6.2627778 | O8: 2.6643342 | P8: 3.7430705 | Q8: -0.098660748 | R8: 1.088043 | S8: 0.80158051 | T8: -0.96501646 | U8: -0.23855089 | V8: 2.5389306 | AF8: 52
A9: 2 | AF9: 30
A10: 3 | AF10: 28
A11: 4 | AF11: 18
A12: 5 | AF12: 11
A13: 6 | AF13: 11.3
A14: 7 | AF14: 11.2
A15: 8 | AF15: 6.3
A16: 9 | AF16: 9.7
A17: 10 | AF17: 11.7
A18: 11 | AF18: 8.9
A19: 12
A20: 13 | AF20: =SUM(AF8:AF18) -> 198.1
A21: 14
A22: 15
A23: 16
A24: 17
A25: 18
A26: 19
A27: 20
A28: 21
A29: 22
A30: 23
A31: 24
A32: 25
AA38: =SUM(AA8:AA34) -> 0
AA39: Expected cost

Sheet Schedule
A1: TEAM | C1: Playoffs | D1: W1 | E1: W2 | F1: W3 | G1: W4 | H1: W5 | I1: W6 | J1: W7 | K1: W8 | L1: W9 | M1: W10 | N1: W11 | O1: W12 | P1: W13 | Q1: W14 | R1: W15 | S1: W16 | T1: W17 | U1: W18 | V1: W19 | W1: W20 | X1: W21 | Y1: W22 | Z1: W23 | AA1: W24
A2: Atlanta Hawks | B2: ATL | C2: =SUM(X2:AA2) -> 14 | D2: 2 | E2: 4 | F2: 4 | G2: 4 | H2: 3 | I2: 4 | J2: 3 | K2: 2 | L2: 4 | M2: 3 | N2: 3 | O2: 4 | P2: 3 | Q2: 4 | R2: 4 | S2: 4 | T2: 3 | U2: 4 | V2: 2 | W2: 4 | X2: 4 | Y2: 3 | Z2: 3 | AA2: 4
A3: Boston Celtics | B3: BOS | C3: =SUM(X3:AA3) -> 13 | D3: 3 | E3: 3 | F3: 4 | G3: 3 | H3: 4 | I3: 4 | J3: 3 | K3: 3 | L3: 3 | M3: 3 | N3: 4 | O3: 3 | P3: 4 | Q3: 4 | R3: 3 | S3: 4 | T3: 3 | U3: 5 | V3: 3 | W3: 3 | X3: 3 | Y3: 3 | Z3: 4 | AA3: 3
A4: Brooklyn Nets | B4: BKN | C4: =SUM(X4:AA4) -> 14 | D4: 3 | E4: 4 | F4: 3 | G4: 4 | H4: 3 | I4: 3 | J4: 3 | K4: 4 | L4: 4 | M4: 3 | N4: 3 | O4: 4 | P4: 3 | Q4: 4 | R4: 3 | S4: 4 | T4: 3 | U4: 4 | V4: 3 | W4: 3 | X4: 3 | Y4: 4 | Z4: 3 | AA4: 4
A5: Charlotte Hornets | B5: CHA | C5: =SUM(X5:AA5) -> 14 | D5: 3 | E5: 4 | F5: 4 | G5: 4 | H5: 3 | I5: 4 | J5: 3 | K5: 3 | L5: 4 | M5: 2 | N5: 3 | O5: 3 | P5: 3 | Q5: 4 | R5: 4 | S5: 3 | T5: 4 | U5: 4 | V5: 3 | W5: 3 | X5: 3 | Y5: 4 | Z5: 3 | AA5: 4
A6: Chicago Bulls | B6: CHI | C6: =SUM(X6:AA6) -> 15 | D6: 3 | E6: 3 | F6: 3 | G6: 4 | H6: 4 | I6: 4 | J6: 3 | K6: 3 | L6: 3 | M6: 3 | N6: 4 | O6: 3 | P6: 3 | Q6: 4 | R6: 4 | S6: 3 | T6: 4 | U6: 4 | V6: 2 | W6: 3 | X6: 3 | Y6: 4 | Z6: 4 | AA6: 4
A7: Cleveland Cavaliers | B7: CLE | C7: =SUM(X7:AA7) -> 14 | D7: 3 | E7: 4 | F7: 4 | G7: 3 | H7: 3 | I7: 3 | J7: 4 | K7: 4 | L7: 4 | M7: 2 | N7: 4 | O7: 3 | P7: 4 | Q7: 3 | R7: 3 | S7: 4 | T7: 3 | U7: 3 | V7: 4 | W7: 3 | X7: 4 | Y7: 3 | Z7: 4 | AA7: 3
A8: Dallas Mavericks | B8: DAL | C8: =SUM(X8:AA8) -> 14 | D8: 2 | E8: 4 | F8: 3 | G8: 3 | H8: 4 | I8: 2 | J8: 4 | K8: 4 | L8: 3 | M8: 3 | N8: 4 | O8: 4 | P8: 3 | Q8: 4 | R8: 4 | S8: 3 | T8: 3 | U8: 4 | V8: 3 | W8: 4 | X8: 3 | Y8: 4 | Z8: 4 | AA8: 3
